Workbook

Sheet Menu
A2: FRSH Daily Menu
A5: Days | B5: Recipe Code | C5: Recipe Names | D5: Category
A6: Sunday | B6: ='Master Recipes'!A10 -> RCP-Frsh-00007 | C6: Curry nomi Pasta | D6: Plates
A7: Sunday | B7: ='Master Recipes'!A14 -> RCP-Frsh-00011 | C7: Chicken Molokheya | D7: Plates
A8: Sunday | B8: ='Master Recipes'!A15 -> RCP-Frsh-00012 | C8: Egg avocado Truffle | D8: Sandwich
A9: Sunday | B9: ='Master Recipes'!A11 -> RCP-Frsh-00008 | C9: Black Lemon Steak | D9: Plates
A10: Sunday | B10: ='Master Recipes'!A16 -> RCP-Frsh-00013 | C10: Tuna truffle | D10: Sandwich
A11: Sunday | B11: ='Master Recipes'!A17 -> RCP-Frsh-00014 | C11: Chicken pumpkin | D11: Plates
A12: Sunday | B12: ='Master Recipes'!A13 -> RCP-Frsh-00010 | C12: Philly steak mushroom / Sandwich | D12: Sandwich
A13: Sunday | B13: ='Master Recipes'!A12 -> RCP-Frsh-00009 | C13: Musakhan chicken | D13: Plates
A14: Sunday | B14: ='Master Recipes'!A46 -> RCP-Frsh-00042 | C14: Ranch Salad | D14: Salad
A15: Sunday | B15: ='Master Recipes'!A48 -> RCP-Frsh-00044 | C15: Tuna Salad | D15: Salad
A16: Sunday | B16: ='Master Recipes'!A49 -> RCP-Frsh-00045 | C16: Beetroot Salad | D16: Salad
A17: Sunday | B17: ='Master Recipes'!A47 -> RCP-Frsh-00043 | C17: Grilled ranch salad | D17: Salad
A18: Sunday | B18: ='Master Recipes'!A50 -> RCP-Frsh-00046 | C18: Red beans salad | D18: Salad
A19: Sunday | B19: ='Master Recipes'!A45 -> RCP-Frsh-00041 | C19: Grilled Halloumi salad | D19: Salad
A20: Sunday | B20: ='Master Recipes'!A39 -> RCP-Frsh-00047 | C20: Mango Oats | D20: Snack
A21: Sunday | B21: ='Master Recipes'!A43 -> RCP-Frsh-00039 | C21: Coconut Dates Balls | D21: Snack
A22: Sunday | B22: ='Master Recipes'!A44 -> RCP-Frsh-00040 | C22: Cinnamon Dates Balls | D22: Snack
A23: Sunday | B23: ='Master Recipes'!A40 -> RCP-Frsh-00036 | C23: Peanut Butter Oats | D23: Snack
A24: Sunday | B24: ='Master Recipes'!A41 -> RCP-Frsh-00037 | C24: Arabian Sesame Dates Balls | D24: Snack
A25: Sunday | B25: ='Master Recipes'!A42 -> RCP-Frsh-00038 | C25: Chocolate Date Balls | D25: Snack
A26: Monday | B26: ='Master Recipes'!A20 -> RCP-Frsh-00017 | C26: Egg Mashed Potato | D26: Plates
A27: Monday | B27: ='Master Recipes'!A21 -> RCP-Frsh-00018 | C27: Caramelized PB and honey crunch | D27: Sandwich
A28: Monday | B28: ='Master Recipes'!A19 -> RCP-Frsh-00016 | C28: Rustic ragu pasta | D28: Plates
A29: Monday | B29: ='Master Recipes'!A6 -> RCP-Frsh-00003 | C29: Misto chicken broccoli | D29: Plates
A30: Monday | B30: ='Master Recipes'!A22 -> RCP-Frsh-00019 | C30: Umami Truffle streak | D30: Sandwich
A31: Monday | B31: ='Master Recipes'!A38 -> RCP-Frsh-00035 | C31: Mix Cheese | D31: Sandwich
A32: Monday | B32: ='Master Recipes'!A23 -> RCP-Frsh-00020 | C32: Tomato halloumi grilled | D32: Sandwich
A33: Monday | B33: ='Master Recipes'!A18 -> RCP-Frsh-00015 | C33: Chicken Creamy Mint | D33: Plates
A34: Monday | B34: =B14 -> RCP-Frsh-00042 | C34: Ranch Salad | D34: Salad
A35: Monday | B35: =B15 -> RCP-Frsh-00044 | C35: Tuna Salad | D35: Salad
A36: Monday | B36: =B16 -> RCP-Frsh-00045 | C36: Beetroot Salad | D36: Salad
A37: Monday | B37: =B17 -> RCP-Frsh-00043 | C37: Grilled ranch salad | D37: Salad
A38: Monday | B38: =B18 -> RCP-Frsh-00046 | C38: Red beans salad | D38: Salad
A39: Monday | B39: =B19 -> RCP-Frsh-00041 | C39: Grilled Halloumi salad | D39: Salad
A40: Monday | B40: =B20 -> RCP-Frsh-00047 | C40: Mango Oats | D40: Snack
A41: Monday | B41: =B21 -> RCP-Frsh-00039 | C41: Coconut Dates Balls | D41: Snack
A42: Monday | B42: =B22 -> RCP-Frsh-00040 | C42: Cinnamon Dates Balls | D42: Snack
A43: Monday | B43: =B23 -> RCP-Frsh-00036 | C43: Peanut Butter Oats | D43: Snack
...

Sheet Master Recipes
A1: 📘 Master Recipes – Academia School
A3: Main Recipe ID | B3: Recipe Name | C3: Brand Code | D3: Customer Name | E3: Category | F3: Standard No. of Portions | G3: Weight per Portion (g) | H3: Size of Portion | I3: Has Sub Recipe? | J3: Sub Recipe ID | K3: Sub Recipe Name | L3: Sub Recipe No. of Portions | M3: Total Ingredient Count | N3: Total Batch Wt (g) * | O3: Recipe Standard Yield % | P3: Targeted Wastage % | Q3: Food Cost Per Portion | R3: Packaging Cost | S3: Labor Cost | T3: Delivery Cost | U3: Overheads | V3: Other Costs | W3: Total Cost | X3: Margin %age | Y3: Profit | Z3: Sale Price | AA3: Remark
A4: {=_xlfn.UNIQUE('Recipe Ingredients'!A5:A838)} -> RCP-Frsh-00001 | B4: =VLOOKUP(A4,'Recipe Ingredients'!$A$5:$D$838,4,0) -> Avocado egg Ranch
A5: RCP-Frsh-00002 | B5: =VLOOKUP(A5,'Recipe Ingredients'!$A$5:$D$838,4,0) -> Spinach steak
A6: RCP-Frsh-00003 | B6: =VLOOKUP(A6,'Recipe Ingredients'!$A$5:$D$838,4,0) -> Misto chicken broccoli
A7: RCP-Frsh-00004 | B7: =VLOOKUP(A7,'Recipe Ingredients'!$A$5:$D$838,4,0) -> Honey Pecan Halloumi
A8: RCP-Frsh-00005 | B8: =VLOOKUP(A8,'Recipe Ingredients'!$A$5:$D$838,4,0) -> Pasta Creamy Potato
A9: RCP-Frsh-00006 | B9: =VLOOKUP(A9,'Recipe Ingredients'!$A$5:$D$838,4,0) -> Chicken creamy lemon
A10: RCP-Frsh-00007 | B10: =VLOOKUP(A10,'Recipe Ingredients'!$A$5:$D$838,4,0) -> Curry nomi Pasta
A11: RCP-Frsh-00008 | B11: =VLOOKUP(A11,'Recipe Ingredients'!$A$5:$D$838,4,0) -> Black Lemon Steak
A12: RCP-Frsh-00009 | B12: =VLOOKUP(A12,'Recipe Ingredients'!$A$5:$D$838,4,0) -> Musakhan chicken
A13: RCP-Frsh-00010 | B13: =VLOOKUP(A13,'Recipe Ingredients'!$A$5:$D$838,4,0) -> Philly steak mushroom
A14: RCP-Frsh-00011 | B14: =VLOOKUP(A14,'Recipe Ingredients'!$A$5:$D$838,4,0) -> Chicken Molokheya
A15: RCP-Frsh-00012 | B15: =VLOOKUP(A15,'Recipe Ingredients'!$A$5:$D$838,4,0) -> Egg avocado Truffle
A16: RCP-Frsh-00013 | B16: =VLOOKUP(A16,'Recipe Ingredients'!$A$5:$D$838,4,0) -> Tuna truffle
... A50: RCP-Frsh-00046 | B50: =VLOOKUP(A50,'Recipe Ingredients'!$A$5:$D$838,4,0) -> Red Beans Salad

Sheet Recipe Ingredients
A1: 📘 Master Recipe Ingredients – FRSH
A3: ▶ CONSOLIDATED INGREDIENT MASTER — FRSH Main + Sub Recipes
A4: Recipe code | B4: Category | C4: Customer Name | D4: Recipe Name | E4: Day | F4: Section | G4: Sub Recipe Description | H4: Item Code | I4: Item / Ingredient | J4: UOM | K4: Standard UOM | L4: NET Qty req per Batch (g/pcs) | M4: GROSS Qty req per Batch (g/pcs) | N4: Yield % | O4: No. of portions per batch | P4: Qty req per portion | Q4: Purchase Price Standard UOM | R4: Food Cost per portion | S4: Veriable cost 10% | T4: Total Food Cost | U4: Labour Cost | V4: Delivery Cost | W4: Packing Cost | X4: Total cost | Y4: Buchery Cutting /Portion size
A5: RCP-Frsh-00001 | B5: Sandwiches | C5: Frsh | D5: Avocado egg Ranch | E5: Saturday | F5: TrayLine Section | H5: =IFERROR(VLOOKUP(I5,'Raw material list'!$A$3:$C$695,3,0),"") -> BKR1-1327 | I5: Bread Sliced Brown Med-400001 | J5: Slice | K5: =IFERROR(VLOOKUP(I5,'Raw material list'!$A$3:$E$695,5,0),"") -> Slice | L5: 10 | M5: =L5/N5*100 -> 10 | N5: 100 | O5: 10 | P5: =IFERROR(L5/O5,0) -> 1 | Q5: =IFERROR(VLOOKUP(I5,'Raw material list'!$A$3:$F$695,6,0),"") -> 0.22222222 | R5: =IFERROR(Q5*P5,0) -> 0.22222222 | S5: =R5*10% -> 0.022222222 | T5: =R5+S5 -> 0.24444444 | U5: =T5*10% -> 0.024444444 | V5: =T5*1% -> 0.0024444444 | W5: =T5*1% -> 0.0024444444 | X5: =T5+U5+V5+W5 -> 0.27377778
A6: RCP-Frsh-00001 | B6: Sandwiches | C6: Frsh | D6: Avocado egg Ranch | E6: Saturday | F6: Hot Section | H6: =IFERROR(VLOOKUP(I6,'Raw material list'!$A$3:$C$695,3,0),"") -> PLT1-37 | I6: Eggs | J6: Each | K6: =IFERROR(VLOOKUP(I6,'Raw material list'!$A$3:$E$695,5,0),"") -> Each | L6: 12 | M6: =L6/N6*100 -> 12 | N6: 100 | O6: 10 | P6: =IFERROR(L6/O6,0) -> 1.2 | Q6: =IFERROR(VLOOKUP(I6,'Raw material list'!$A$3:$F$695,6,0),"") -> 0.483 | R6: =IFERROR(Q6*P6,0) -> 0.5796 | S6: =R6*10% -> 0.05796 | T6: =R6+S6 -> 0.63756 | U6: =T6*10% -> 0.063756 | V6: =T6*1% -> 0.0063756 | W6: =T6*1% -> 0.0063756 | X6: =T6+U6+V6+W6 -> 0.7140672
A7: RCP-Frsh-00001 | B7: Sandwiches | C7: Frsh | D7: Avocado egg Ranch | E7: Saturday | F7: Hot Section | H7: =IFERROR(VLOOKUP(I7,'Raw material list'!$A$3:$C$695,3,0),"") -> PRD1-4787 | I7: Fresh Avocado | J7: Gram | K7: =IFERROR(VLOOKUP(I7,'Raw material list'!$A$3:$E$695,5,0),"") -> Gram | L7: 61.12 | M7: =L7/N7*100 -> 150.29508 | N7: 40.666667 | O7: 10 | P7: =IFERROR(L7/O7,0) -> 6.112 | Q7: =IFERROR(VLOOKUP(I7,'Raw material list'!$A$3:$F$695,6,0),"") -> 0.078624079 | R7: =IFERROR(Q7*P7,0) -> 0.48055037 | S7: =R7*10% -> 0.048055037 | T7: =R7+S7 -> 0.52860541 | U7: =T7*10% -> 0.052860541 | V7: =T7*1% -> 0.0052860541 | W7: =T7*1% -> 0.0052860541 | X7: =T7+U7+V7+W7 -> 0.59203805
A8: RCP-Frsh-00001 | B8: Sandwiches | C8: Frsh | D8: Avocado egg Ranch | E8: Saturday | F8: Hot Section | H8: =IFERROR(VLOOKUP(I8,'Raw material list'!$A$3:$C$695,3,0),"") -> DRS1-114 | I8: Sea Salt(737 Gram) | J8: Gram | K8: =IFERROR(VLOOKUP(I8,'Raw material list'!$A$3:$E$695,5,0),"") -> Gram | L8: 3.5 | M8: =L8/N8*100 -> 3.5 | N8: 100 | O8: 10 | P8: =IFERROR(L8/O8,0) -> 0.35 | Q8: =IFERROR(VLOOKUP(I8,'Raw material list'!$A$3:$F$695,6,0),"") -> 0.0047489824 | R8: =IFERROR(Q8*P8,0) -> 0.0016621438 | S8: =R8*10% -> 0.00016621438 | T8: =R8+S8 -> 0.0018283582 | U8: =T8*10% -> 0.00018283582 | V8: =T8*1% -> 1.8283582e-05 | W8: =T8*1% -> 1.8283582e-05 | X8: =T8+U8+V8+W8 -> 0.0020477612
A9: RCP-Frsh-00001 | B9: Sandwiches | C9: Frsh | D9: Avocado egg Ranch | E9: Saturday | F9: Hot Section | H9: =IFERROR(VLOOKUP(I9,'Raw material list'!$A$3:$C$695,3,0),"") -> DRS6-537 | I9: Spices Pepper Black Powder(1 Kg) | J9: Gram | K9: =IFERROR(VLOOKUP(I9,'Raw material list'!$A$3:$E$695,5,0),"") -> Gram | L9: 0.855 | M9: =L9/N9*100 -> 0.855 | N9: 100 | O9: 10 | P9: =IFERROR(L9/O9,0) -> 0.0855 | Q9: =IFERROR(VLOOKUP(I9,'Raw material list'!$A$3:$F$695,6,0),"") -> 0.035 | R9: =IFERROR(Q9*P9,0) -> 0.0029925 | S9: =R9*10% -> 0.00029925 | T9: =R9+S9 -> 0.00329175 | U9: =T9*10% -> 0.000329175 | V9: =T9*1% -> 3.29175e-05 | W9: =T9*1% -> 3.29175e-05 | X9: =T9+U9+V9+W9 -> 0.00368676
A10: RCP-Frsh-00001 | B10: Sandwiches | C10: Frsh | D10: Avocado egg Ranch | E10: Saturday | F10: Hot Section | H10: =IFERROR(VLOOKUP(I10,'Raw material list'!$A$3:$C$695,3,0),"") -> DRS6-309 | I10: Spice Pepper White Powder | J10: Gram | K10: =IFERROR(VLOOKUP(I10,'Raw material list'!$A$3:$E$695,5,0),"") -> Gram | L10: 0.855 | M10: =L10/N10*100 -> 0.855 | N10: 100 | O10: 10 | P10: =IFERROR(L10/O10,0) -> 0.0855 | Q10: =IFERROR(VLOOKUP(I10,'Raw material list'!$A$3:$F$695,6,0),"") -> 0.028 | R10: =IFERROR(Q10*P10,0) -> 0.002394 | S10: =R10*10% -> 0.0002394 | T10: =R10+S10 -> 0.0026334 | U10: =T10*10% -> 0.00026334 | V10: =T10*1% -> 2.6334e-05 | W10: =T10*1% -> 2.6334e-05 | X10: =T10+U10+V10+W10 -> 0.002949408
A11: RCP-Frsh-00001 | B11: Sandwiches | C11: Frsh | D11: Avocado egg Ranch | E11: Saturday | F11: Hot Section | H11: =IFERROR(VLOOKUP(I11,'Raw material list'!$A$3:$C$695,3,0),"") -> DRS6-1570 | I11: Dried Oregano | J11: Gram | K11: =IFERROR(VLOOKUP(I11,'Raw material list'!$A$3:$E$695,5,0),"") -> Gram | L11: 0.611 | M11: =L11/N11*100 -> 0.611 | N11: 100 | O11: 10 | P11: =IFERROR(L11/O11,0) -> 0.0611 | Q11: =IFERROR(VLOOKUP(I11,'Raw material list'!$A$3:$F$695,6,0),"") -> 0.028 | R11: =IFERROR(Q11*P11,0) -> 0.0017108 | S11: =R11*10% -> 0.00017108 | T11: =R11+S11 -> 0.00188188 | U11: =T11*10% -> 0.000188188 | V11: =T11*1% -> 1.88188e-05 | W11: =T11*1% -> 1.88188e-05 | X11: =T11+U11+V11+W11 -> 0.0021077056
A12: RCP-Frsh-00001 | B12: Sandwiches | C12: Frsh | D12: Avocado egg Ranch | E12: Saturday | F12: Hot Section | G12: Ranch Sauce | H12: =IFERROR(VLOOKUP(I12,'Raw material list'!$A$3:$C$695,3,0),"") -> DRS1-1652 | I12: Light Mayonnaise | J12: Gram | K12: =IFERROR(VLOOKUP(I12,'Raw material list'!$A$3:$E$695,5,0),"") -> Gram | L12: 67.64 | M12: =L12/N12*100 -> 67.64 | N12: 100 | O12: 10 | P12: =IFERROR(L12/O12,0) -> 6.764 | Q12: =IFERROR(VLOOKUP(I12,'Raw material list'!$A$3:$F$695,6,0),"") -> 0.0128 | R12: =IFERROR(Q12*P12,0) -> 0.0865792 | S12: =R12*10% -> 0.00865792 | T12: =R12+S12 -> 0.09523712 | U12: =T12*10% -> 0.009523712 | V12: =T12*1% -> 0.0009523712 | W12: =T12*1% -> 0.0009523712 | X12: =T12+U12+V12+W12 -> 0.10666557
A13: RCP-Frsh-00001 | B13: Sandwiches | C13: Frsh | D13: Avocado egg Ranch | E13: Saturday | F13: Hot Section | G13: Ranch Sauce | H13: =IFERROR(VLOOKUP(I13,'Raw material list'!$A$3:$C$695,3,0),"") -> DRY1-1717 | I13: Cheese Cream Philadelphia (1360 GR) | J13: Gram | K13: =IFERROR(VLOOKUP(I13,'Raw material list'!$A$3:$E$695,5,0),"") -> Gram | L13: 33.82 | M13: =L13/N13*100 -> 33.82 | N13: 100 | O13: 10 | P13: =IFERROR(L13/O13,0) -> 3.382 | Q13: =IFERROR(VLOOKUP(I13,'Raw material list'!$A$3:$F$695,6,0),"") -> 0.037 | R13: =IFERROR(Q13*P13,0) -> 0.125134 | S13: =R13*10% -> 0.0125134 | T13: =R13+S13 -> 0.1376474 | U13: =T13*10% -> 0.01376474 | V13: =T13*1% -> 0.001376474 | W13: =T13*1% -> 0.001376474 | X13: =T13+U13+V13+W13 -> 0.15416509
A14: RCP-Frsh-00001 | B14: Sandwiches | C14: Frsh | D14: Avocado egg Ranch | E14: Saturday | F14: Hot Section | G14: Ranch Sauce | H14: =IFERROR(VLOOKUP(I14,'Raw material list'!$A$3:$C$695,3,0),"") -> PRD1-209 | I14: Fresh Lemon | J14: Gram | K14: =IFERROR(VLOOKUP(I14,'Raw material list'!$A$3:$E$695,5,0),"") -> Gram | L14: 0.67 | M14: =L14/N14*100 -> 1.7631579 | N14: 38 | O14: 10 | P14: =IFERROR(L14/O14,0) -> 0.067 | Q14: =IFERROR(VLOOKUP(I14,'Raw material list'!$A$3:$F$695,6,0),"") -> 0.010088272 | R14: =IFERROR(Q14*P14,0) -> 0.00067591425 | S14: =R14*10% -> 6.7591425e-05 | T14: =R14+S14 -> 0.00074350567 | U14: =T14*10% -> 7.4350567e-05 | V14: =T14*1% -> 7.4350567e-06 | W14: =T14*1% -> 7.4350567e-06 | X14: =T14+U14+V14+W14 -> 0.00083272636
A15: RCP-Frsh-00001 | B15: Sandwiches | C15: Frsh | D15: Avocado egg Ranch | E15: Saturday | F15: Hot Section | G15: Ranch Sauce | H15: =IFERROR(VLOOKUP(I15,'Raw material list'!$A$3:$C$695,3,0),"") -> DRS6-537 | I15: Spices Pepper Black Powder(1 Kg) | J15: Gram | K15: =IFERROR(VLOOKUP(I15,'Raw material list'!$A$3:$E$695,5,0),"") -> Gram | L15: 0.27 | M15: =L15/N15*100 -> 0.27 | N15: 100 | O15: 10 | P15: =IFERROR(L15/O15,0) -> 0.027 | Q15: =IFERROR(VLOOKUP(I15,'Raw material list'!$A$3:$F$695,6,0),"") -> 0.035 | R15: =IFERROR(Q15*P15,0) -> 0.000945 | S15: =R15*10% -> 9.45e-05 | T15: =R15+S15 -> 0.0010395 | U15: =T15*10% -> 0.00010395 | V15: =T15*1% -> 1.0395e-05 | W15: =T15*1% -> 1.0395e-05 | X15: =T15+U15+V15+W15 -> 0.00116424
A16: RCP-Frsh-00001 | B16: Sandwiches | C16: Frsh | D16: Avocado egg Ranch | E16: Saturday | F16: Hot Section | G16: Ranch Sauce | H16: =IFERROR(VLOOKUP(I16,'Raw material list'!$A$3:$C$695,3,0),"") -> DRS1-114 | I16: Sea Salt(737 Gram) | J16: Gram | K16: =IFERROR(VLOOKUP(I16,'Raw material list'!$A$3:$E$695,5,0),"") -> Gram | L16: 0.27 | M16: =L16/N16*100 -> 0.27 | N16: 100 | O16: 10 | P16: =IFERROR(L16/O16,0) -> 0.027 | Q16: =IFERROR(VLOOKUP(I16,'Raw material list'!$A$3:$F$695,6,0),"") -> 0.0047489824 | R16: =IFERROR(Q16*P16,0) -> 0.00012822252 | S16: =R16*10% -> 1.2822252e-05 | T16: =R16+S16 -> 0.00014104478 | U16: =T16*10% -> 1.4104478e-05 | V16: =T16*1% -> 1.4104478e-06 | W16: =T16*1% -> 1.4104478e-06 | X16: =T16+U16+V16+W16 -> 0.00015797015
A17: RCP-Frsh-00001 | B17: Sandwiches | C17: Frsh | D17: Avocado egg Ranch | E17: Saturday | F17: Hot Section | G17: Ranch Sauce | H17: =IFERROR(VLOOKUP(I17,'Raw material list'!$A$3:$C$695,3,0),"") -> WAT-001 | I17: Tap Water-cooking | J17: Ml | K17: =IFERROR(VLOOKUP(I17,'Raw material list'!$A$3:$E$695,5,0),"") -> Ml | L17: 6.76 | M17: =L17/N17*100 -> 6.76 | N17: 100 | O17: 10 | P17: =IFERROR(L17/O17,0) -> 0.676 | Q17: =IFERROR(VLOOKUP(I17,'Raw material list'!$A$3:$F$695,6,0),"") -> 8e-05 | R17: =IFERROR(Q17*P17,0) -> 5.408e-05 | S17: =R17*10% -> 5.408e-06 | T17: =R17+S17 -> 5.9488e-05 | U17: =T17*10% -> 5.9488e-06 | V17: =T17*1% -> 5.9488e-07 | W17: =T17*1% -> 5.9488e-07 | X17: =T17+U17+V17+W17 -> 6.662656e-05
A18: RCP-Frsh-00001 | B18: Sandwiches | C18: Frsh | D18: Avocado egg Ranch | E18: Saturday | F18: Hot Section | G18: Ranch Sauce | H18: =IFERROR(VLOOKUP(I18,'Raw material list'!$A$3:$C$695,3,0),"") -> DRS1-5273 | I18: Sauce Worcester L&P 3.78 Ltr | J18: Ml | K18: =IFERROR(VLOOKUP(I18,'Raw material list'!$A$3:$E$695,5,0),"") -> Ml | L18: 1.35 | M18: =L18/N18*100 -> 1.35 | N18: 100 | O18: 10 | P18: =IFERROR(L18/O18,0) -> 0.135 | Q18: =IFERROR(VLOOKUP(I18,'Raw material list'!$A$3:$F$695,6,0),"") -> 0.018518519 | R18: =IFERROR(Q18*P18,0) -> 0.0025 | S18: =R18*10% -> 0.00025 | T18: =R18+S18 -> 0.00275 | U18: =T18*10% -> 0.000275 | V18: =T18*1% -> 2.75e-05 | W18: =T18*1% -> 2.75e-05 | X18: =T18+U18+V18+W18 -> 0.00308
A19: RCP-Frsh-00001 | B19: Sandwiches | C19: Frsh | D19: Avocado egg Ranch | E19: Saturday | F19: Hot Section | G19: Ranch Sauce | H19: =IFERROR(VLOOKUP(I19,'Raw material list'!$A$3:$C$695,3,0),"") -> DRS1-5269 | I19: Maple Syrup Amber 375 ml | J19: Ml | K19: =IFERROR(VLOOKUP(I19,'Raw material list'!$A$3:$E$695,5,0),"") -> Ml | L19: 1.35 | M19: =L19/N19*100 -> 1.35 | N19: 100 | O19: 10 | P19: =IFERROR(L19/O19,0) -> 0.135 | Q19: =IFERROR(VLOOKUP(I19,'Raw material list'!$A$3:$F$695,6,0),"") -> 0.10666667 | R19: =IFERROR(Q19*P19,0) -> 0.0144 | S19: =R19*10% -> 0.00144 | T19: =R19+S19 -> 0.01584 | U19: =T19*10% -> 0.001584 | V19: =T19*1% -> 0.0001584 | W19: =T19*1% -> 0.0001584 | X19: =T19+U19+V19+W19 -> 0.0177408
A20: RCP-Frsh-00001 | B20: Sandwiches | C20: Frsh | D20: Avocado egg Ranch | E20: Saturday | F20: Hot Section | G20: Ranch Sauce | H20: =IFERROR(VLOOKUP(I20,'Raw material list'!$A$3:$C$695,3,0),"") -> DRY2-1858 | I20: Cooking Cream 1 Ltr | J20: Ml | K20: =IFERROR(VLOOKUP(I20,'Raw material list'!$A$3:$E$695,5,0),"") -> Ml | L20: 6.76 | M20: =L20/N20*100 -> 6.76 | N20: 100 | O20: 10 | P20: =IFERROR(L20/O20,0) -> 0.676 | Q20: =IFERROR(VLOOKUP(I20,'Raw material list'!$A$3:$F$695,6,0),"") -> 0.00988 | R20: =IFERROR(Q20*P20,0) -> 0.00667888 | S20: =R20*10% -> 0.000667888 | T20: =R20+S20 -> 0.007346768 | U20: =T20*10% -> 0.0007346768 | V20: =T20*1% -> 7.346768e-05 | W20: =T20*1% -> 7.346768e-05 | X20: =T20+U20+V20+W20 -> 0.0082283802
A21: RCP-Frsh-00001 | B21: Sandwiches | C21: Frsh | D21: Avocado egg Ranch | E21: Saturday | F21: Hot Section | G21: Ranch Sauce | H21: =IFERROR(VLOOKUP(I21,'Raw material list'!$A$3:$C$695,3,0),"") -> PRD1-221 | I21: Fresh Mint | J21: Gram | K21: =IFERROR(VLOOKUP(I21,'Raw material list'!$A$3:$E$695,5,0),"") -> Gram | L21: 1.082 | M21: =L21/N21*100 -> 1.8612385 | N21: 58.133333 | O21: 10 | P21: =IFERROR(L21/O21,0) -> 0.1082 | Q21: =IFERROR(VLOOKUP(I21,'Raw material list'!$A$3:$F$695,6,0),"") -> 0.0068846816 | R21: =IFERROR(Q21*P21,0) -> 0.00074492255 | S21: =R21*10% -> 7.4492255e-05 | T21: =R21+S21 -> 0.0008194148 | U21: =T21*10% -> 8.194148e-05 | V21: =T21*1% -> 8.194148e-06 | W21: =T21*1% -> 8.194148e-06 | X21: =T21+U21+V21+W21 -> 0.00091774458
A22: RCP-Frsh-00001 | B22: Sandwiches | C22: Frsh | D22: Avocado egg Ranch | E22: Saturday | F22: TrayLine Section | G22: Garnish | H22: =IFERROR(VLOOKUP(I22,'Raw material list'!$A$3:$C$695,3,0),"") -> PRD1-235 | I22: Fresh Rocket | J22: Gram | K22: =IFERROR(VLOOKUP(I22,'Raw material list'!$A$3:$E$695,5,0),"") -> Gram | L22: 30 | M22: =L22/N22*100 -> 92.783505 | N22: 32.333333 | O22: 10 | P22: =IFERROR(L22/O22,0) -> 3 | Q22: =IFERROR(VLOOKUP(I22,'Raw material list'!$A$3:$F$695,6,0),"") -> 0.012383901 | R22: =IFERROR(Q22*P22,0) -> 0.037151703 | S22: =R22*10% -> 0.0037151703 | T22: =R22+S22 -> 0.040866873 | U22: =T22*10% -> 0.0040866873 | V22: =T22*1% -> 0.00040866873 | W22: =T22*1% -> 0.00040866873 | X22: =T22+U22+V22+W22 -> 0.045770898
A23: RCP-Frsh-00002 | B23: Plates | C23: Frsh | D23: Spinach steak | E23: Saturday | F23: Butchery Section | G23: Beef marination | H23: =IFERROR(VLOOKUP(I23,'Raw material list'!$A$3:$C$695,3,0),"") -> MET2-1051 | I23: Frz Beef Tendrloin Brazil | J23: Gram | K23: =IFERROR(VLOOKUP(I23,'Raw material list'!$A$3:$E$695,5,0),"") -> Gram | L23: 1500 | M23: =L23/N23*100 -> 2918.2879 | N23: 51.4 | O23: 10 | P23: =IFERROR(L23/O23,0) -> 150 | Q23: =IFERROR(VLOOKUP(I23,'Raw material list'!$A$3:$F$695,6,0),"") -> 0.084705882 | R23: =IFERROR(Q23*P23,0) -> 12.705882 | S23: =R23*10% -> 1.2705882 | T23: =R23+S23 -> 13.976471 | U23: =T23*10% -> 1.3976471 | V23: =T23*1% -> 0.13976471 | W23: =T23*1% -> 0.13976471 | X23: =T23+U23+V23+W23 -> 15.653647 | Y23: Beef Tenderloin - Pc - 160 g
A24: RCP-Frsh-00002 | B24: Plates | C24: Frsh | D24: Spinach steak | E24: Saturday | F24: Butchery Section | G24: Beef marination | H24: =IFERROR(VLOOKUP(I24,'Raw material list'!$A$3:$C$695,3,0),"") -> DRS1-1142 | I24: Soya Sauce Kikkoman(Liter) | J24: Gram | K24: =IFERROR(VLOOKUP(I24,'Raw material list'!$A$3:$E$695,5,0),"") -> Ml | L24: 100 | M24: =L24/N24*100 -> 100 | N24: 100 | O24: 10 | P24: =IFERROR(L24/O24,0) -> 10 | Q24: =IFERROR(VLOOKUP(I24,'Raw material list'!$A$3:$F$695,6,0),"") -> 0.02358 | R24: =IFERROR(Q24*P24,0) -> 0.2358 | S24: =R24*10% -> 0.02358 | T24: =R24+S24 -> 0.25938 | U24: =T24*10% -> 0.025938 | V24: =T24*1% -> 0.0025938 | W24: =T24*1% -> 0.0025938 | X24: =T24+U24+V24+W24 -> 0.2905056
A25: RCP-Frsh-00002 | B25: Plates | C25: Frsh | D25: Spinach steak | E25: Saturday | F25: Butchery Section | G25: Beef marination | H25: =IFERROR(VLOOKUP(I25,'Raw material list'!$A$3:$C$695,3,0),"") -> PRD1-4327 | I25: Fresh Garlic Peeled | J25: Gram | K25: =IFERROR(VLOOKUP(I25,'Raw material list'!$A$3:$E$695,5,0),"") -> Gram | L25: 10 | M25: =L25/N25*100 -> 12.5 | N25: 80 | O25: 10 | P25: =IFERROR(L25/O25,0) -> 1 | Q25: =IFERROR(VLOOKUP(I25,'Raw material list'!$A$3:$F$695,6,0),"") -> 0.013 | R25: =IFERROR(Q25*P25,0) -> 0.013 | S25: =R25*10% -> 0.0013 | T25: =R25+S25 -> 0.0143 | U25: =T25*10% -> 0.00143 | V25: =T25*1% -> 0.000143 | W25: =T25*1% -> 0.000143 | X25: =T25+U25+V25+W25 -> 0.016016
A26: RCP-Frsh-00002 | B26: Plates | C26: Frsh | D26: Spinach steak | E26: Saturday | F26: Butchery Section | G26: Beef marination | H26: =IFERROR(VLOOKUP(I26,'Raw material list'!$A$3:$C$695,3,0),"") -> PRD1-209 | I26: Fresh Lemon | J26: Gram | K26: =IFERROR(VLOOKUP(I26,'Raw material list'!$A$3:$E$695,5,0),"") -> Gram | L26: 15 | M26: =L26/N26*100 -> 39.473684 | N26: 38 | O26: 10 | P26: =IFERROR(L26/O26,0) -> 1.5 | Q26: =IFERROR(VLOOKUP(I26,'Raw material list'!$A$3:$F$695,6,0),"") -> 0.010088272 | R26: =IFERROR(Q26*P26,0) -> 0.015132409 | S26: =R26*10% -> 0.0015132409 | T26: =R26+S26 -> 0.016645649 | U26: =T26*10% -> 0.0016645649 | V26: =T26*1% -> 0.00016645649 | W26: =T26*1% -> 0.00016645649 | X26: =T26+U26+V26+W26 -> 0.018643127
A27: RCP-Frsh-00002 | B27: Plates | C27: Frsh | D27: Spinach steak | E27: Saturday | F27: Butchery Section | G27: Beef marination | H27: =IFERROR(VLOOKUP(I27,'Raw material list'!$A$3:$C$695,3,0),"") -> DRS6-537 | I27: Spices Pepper Black Powder(1 Kg) | J27: Gram | K27: =IFERROR(VLOOKUP(I27,'Raw material list'!$A$3:$E$695,5,0),"") -> Gram | L27: 1 | M27: =L27/N27*100 -> 1 | N27: 100 | O27: 10 | P27: =IFERROR(L27/O27,0) -> 0.1 | Q27: =IFERROR(VLOOKUP(I27,'Raw material list'!$A$3:$F$695,6,0),"") -> 0.035 | R27: =IFERROR(Q27*P27,0) -> 0.0035 | S27: =R27*10% -> 0.00035 | T27: =R27+S27 -> 0.00385 | U27: =T27*10% -> 0.000385 | V27: =T27*1% -> 3.85e-05 | W27: =T27*1% -> 3.85e-05 | X27: =T27+U27+V27+W27 -> 0.004312
A28: RCP-Frsh-00002 | B28: Plates | C28: Frsh | D28: Spinach steak | E28: Saturday | F28: Butchery Section | G28: Beef marination | H28: =IFERROR(VLOOKUP(I28,'Raw material list'!$A$3:$C$695,3,0),"") -> WAT-001 | I28: Tap Water-cooking | J28: Gram | K28: =IFERROR(VLOOKUP(I28,'Raw material list'!$A$3:$E$695,5,0),"") -> Ml | L28: 100 | M28: =L28/N28*100 -> 100 | N28: 100 | O28: 10 | P28: =IFERROR(L28/O28,0) -> 10 | Q28: =IFERROR(VLOOKUP(I28,'Raw material list'!$A$3:$F$695,6,0),"") -> 8e-05 | R28: =IFERROR(Q28*P28,0) -> 0.0008 | S28: =R28*10% -> 8e-05 | T28: =R28+S28 -> 0.00088 | U28: =T28*10% -> 8.8e-05 | V28: =T28*1% -> 8.8e-06 | W28: =T28*1% -> 8.8e-06 | X28: =T28+U28+V28+W28 -> 0.0009856
A29: RCP-Frsh-00002 | B29: Plates | C29: Frsh | D29: Spinach steak | E29: Saturday | F29: Butchery Section | G29: Beef marination | H29: =IFERROR(VLOOKUP(I29,'Raw material list'!$A$3:$C$695,3,0),"") -> PRD1-573 | I29: Fresh Spring Onion Green | J29: Gram | K29: =IFERROR(VLOOKUP(I29,'Raw material list'!$A$3:$E$695,5,0),"") -> Gram | L29: 10 | M29: =L29/N29*100 -> 13.69863 | N29: 73 | O29: 10 | P29: =IFERROR(L29/O29,0) -> 1 | Q29: =IFERROR(VLOOKUP(I29,'Raw material list'!$A$3:$F$695,6,0),"") -> 0.0054794521 | R29: =IFERROR(Q29*P29,0) -> 0.0054794521 | S29: =R29*10% -> 0.00054794521 | T29: =R29+S29 -> 0.0060273973 | U29: =T29*10% -> 0.00060273973 | V29: =T29*1% -> 6.0273973e-05 | W29: =T29*1% -> 6.0273973e-05 | X29: =T29+U29+V29+W29 -> 0.0067506849
A30: RCP-Frsh-00002 | B30: Plates | C30: Frsh | D30: Spinach steak | E30: Saturday | F30: Hot Section | G30: Garnish / By Tray Line | H30: =IFERROR(VLOOKUP(I30,'Raw material list'!$A$3:$C$695,3,0),"") -> PRD1-209 | I30: Fresh Lemon | J30: PC | K30: PC | L30: 10 | M30: =L30/N30*100 -> 26.315789 | N30: 38 | O30: 10 | P30: =IFERROR(L30/O30,0) -> 1 | Q30: =IFERROR(VLOOKUP(I30,'Raw material list'!$A$3:$F$695,6,0),"") -> 0.010088272 | R30: =IFERROR(Q30*P30,0) -> 0.010088272 | S30: =R30*10% -> 0.0010088272 | T30: =R30+S30 -> 0.0110971 | U30: =T30*10% -> 0.00110971 | V30: =T30*1% -> 0.000110971 | W30: =T30*1% -> 0.000110971 | X30: =T30+U30+V30+W30 -> 0.012428752
A31: RCP-Frsh-00002 | B31: Plates | C31: Frsh | D31: Spinach steak | E31: Saturday | F31: Hot Section | G31: Garnish / By Tray Line | H31: =IFERROR(VLOOKUP(I31,'Raw material list'!$A$3:$C$695,3,0),"") -> PRD1-194 | I31: Fresh Chives (Ciboulettes) | J31: Gram | K31: =IFERROR(VLOOKUP(I31,'Raw material list'!$A$3:$E$695,5,0),"") -> Gram | L31: 10 | M31: =L31/N31*100 -> 10.869565 | N31: 92 | O31: 10 | P31: =IFERROR(L31/O31,0) -> 1 | Q31: =IFERROR(VLOOKUP(I31,'Raw material list'!$A$3:$F$695,6,0),"") -> 0.11 | R31: =IFERROR(Q31*P31,0) -> 0.11 | S31: =R31*10% -> 0.011 | T31: =R31+S31 -> 0.121 | U31: =T31*10% -> 0.0121 | V31: =T31*1% -> 0.00121 | W31: =T31*1% -> 0.00121 | X31: =T31+U31+V31+W31 -> 0.13552
A32: RCP-Frsh-00002 | B32: Plates | C32: Frsh | D32: Spinach steak | E32: Saturday | F32: Hot Section | G32: Garnish / By Tray Line | H32: =IFERROR(VLOOKUP(I32,'Raw material list'!$A$3:$C$695,3,0),"") -> PRD3-5038 | I32: Fried Onions | J32: Gram | K32: =IFERROR(VLOOKUP(I32,'Raw material list'!$A$3:$E$695,5,0),"") -> Gram | L32: 50 | M32: =L32/N32*100 -> 50 | N32: 100 | O32: 10 | P32: =IFERROR(L32/O32,0) -> 5 | Q32: =IFERROR(VLOOKUP(I32,'Raw material list'!$A$3:$F$695,6,0),"") -> 0.026 | R32: =IFERROR(Q32*P32,0) -> 0.13 | S32: =R32*10% -> 0.013 | T32: =R32+S32 -> 0.143 | U32: =T32*10% -> 0.0143 | V32: =T32*1% -> 0.00143 | W32: =T32*1% -> 0.00143 | X32: =T32+U32+V32+W32 -> 0.16016
A33: RCP-Frsh-00002 | B33: Plates | C33: Frsh | D33: Spinach steak | E33: Saturday | F33: Hot Section | G33: Spinach Sauce | H33: =IFERROR(VLOOKUP(I33,'Raw material list'!$A$3:$C$695,3,0),"") -> PRD2-363 | I33: Frz Spinach(400 Gram) | J33: Gram | K33: =IFERROR(VLOOKUP(I33,'Raw material list'!$A$3:$E$695,5,0),"") -> Gram | L33: 638.97 | M33: =L33/N33*100 -> 638.97 | N33: 100 | O33: 10 | P33: =IFERROR(L33/O33,0) -> 63.897 | Q33: =IFERROR(VLOOKUP(I33,'Raw material list'!$A$3:$F$695,6,0),"") -> 0.005875 | R33: =IFERROR(Q33*P33,0) -> 0.37539488 | S33: =R33*10% -> 0.037539488 | T33: =R33+S33 -> 0.41293436 | U33: =T33*10% -> 0.041293436 | V33: =T33*1% -> 0.0041293436 | W33: =T33*1% -> 0.0041293436 | X33: =T33+U33+V33+W33 -> 0.46248649
A34: RCP-Frsh-00002 | B34: Plates | C34: Frsh | D34: Spinach steak | E34: Saturday | F34: Hot Section | G34: Spinach Sauce | H34: =IFERROR(VLOOKUP(I34,'Raw material list'!$A$3:$C$695,3,0),"") -> DRY2-1008 | I34: Butter 82% Fat(Unsalted) 25 kg | J34: Gram | K34: =IFERROR(VLOOKUP(I34,'Raw material list'!$A$3:$E$695,5,0),"") -> Gram | L34: 63.89 | M34: =L34/N34*100 -> 63.89 | N34: 100 | O34: 10 | P34: =IFERROR(L34/O34,0) -> 6.389 | Q34: =IFERROR(VLOOKUP(I34,'Raw material list'!$A$3:$F$695,6,0),"") -> 0.038 | R34: =IFERROR(Q34*P34,0) -> 0.242782 | S34: =R34*10% -> 0.0242782 | T34: =R34+S34 -> 0.2670602 | U34: =T34*10% -> 0.02670602 | V34: =T34*1% -> 0.002670602 | W34: =T34*1% -> 0.002670602 | X34: =T34+U34+V34+W34 -> 0.29910742
A35: RCP-Frsh-00002 | B35: Plates | C35: Frsh | D35: Spinach steak | E35: Saturday | F35: Hot Section | G35: Spinach Sauce | H35: =IFERROR(VLOOKUP(I35,'Raw material list'!$A$3:$C$695,3,0),"") -> PRD1-4265 | I35: Fresh onion Yellow(Imported) | J35: Gram | K35: =IFERROR(VLOOKUP(I35,'Raw material list'!$A$3:$E$695,5,0),"") -> Gram | L35: 31.94 | M35: =L35/N35*100 -> 37.576471 | N35: 85 | O35: 10 | P35: =IFERROR(L35/O35,0) -> 3.194 | Q35: =IFERROR(VLOOKUP(I35,'Raw material list'!$A$3:$F$695,6,0),"") -> 0.0035294118 | R35: =IFERROR(Q35*P35,0) -> 0.011272941 | S35: =R35*10% -> 0.0011272941 | T35: =R35+S35 -> 0.012400235 | U35: =T35*10% -> 0.0012400235 | V35: =T35*1% -> 0.00012400235 | W35: =T35*1% -> 0.00012400235 | X35: =T35+U35+V35+W35 -> 0.013888264
A36: RCP-Frsh-00002 | B36: Plates | C36: Frsh | D36: Spinach steak | E36: Saturday | F36: Hot Section | G36: Spinach Sauce | H36: =IFERROR(VLOOKUP(I36,'Raw material list'!$A$3:$C$695,3,0),"") -> PRD1-4327 | I36: Fresh Garlic Peeled | J36: Gram | K36: =IFERROR(VLOOKUP(I36,'Raw material list'!$A$3:$E$695,5,0),"") -> Gram | L36: 3.5 | M36: =L36/N36*100 -> 4.375 | N36: 80 | O36: 10 | P36: =IFERROR(L36/O36,0) -> 0.35 | Q36: =IFERROR(VLOOKUP(I36,'Raw material list'!$A$3:$F$695,6,0),"") -> 0.013 | R36: =IFERROR(Q36*P36,0) -> 0.00455 | S36: =R36*10% -> 0.000455 | T36: =R36+S36 -> 0.005005 | U36: =T36*10% -> 0.0005005 | V36: =T36*1% -> 5.005e-05 | W36: =T36*1% -> 5.005e-05 | X36: =T36+U36+V36+W36 -> 0.0056056
A37: RCP-Frsh-00002 | B37: Plates | C37: Frsh | D37: Spinach steak | E37: Saturday | F37: Hot Section | G37: Spinach Sauce | H37: =IFERROR(VLOOKUP(I37,'Raw material list'!$A$3:$C$695,3,0),"") -> DRS5-980 | I37: Flour Cake Special (all purpose) | J37: Gram | K37: =IFERROR(VLOOKUP(I37,'Raw material list'!$A$3:$E$695,5,0),"") -> Gram | L37: 12.77 | M37: =L37/N37*100 -> 12.77 | N37: 100 | O37: 10 | P37: =IFERROR(L37/O37,0) -> 1.277 | Q37: =IFERROR(VLOOKUP(I37,'Raw material list'!$A$3:$F$695,6,0),"") -> 0.001 | R37: =IFERROR(Q37*P37,0) -> 0.001277 | S37: =R37*10% -> 0.0001277 | T37: =R37+S37 -> 0.0014047 | U37: =T37*10% -> 0.00014047 | V37: =T37*1% -> 1.4047e-05 | W37: =T37*1% -> 1.4047e-05 | X37: =T37+U37+V37+W37 -> 0.001573264
A38: RCP-Frsh-00002 | B38: Plates | C38: Frsh | D38: Spinach steak | E38: Saturday | F38: Hot Section | G38: Spinach Sauce | H38: =IFERROR(VLOOKUP(I38,'Raw material list'!$A$3:$C$695,3,0),"") -> DRY2-1858 | I38: Cooking Cream 1 Ltr | J38: Ml | K38: =IFERROR(VLOOKUP(I38,'Raw material list'!$A$3:$E$695,5,0),"") -> Ml | L38: 798.72 | M38: =L38/N38*100 -> 798.72 | N38: 100 | O38: 10 | P38: =IFERROR(L38/O38,0) -> 79.872 | Q38: =IFERROR(VLOOKUP(I38,'Raw material list'!$A$3:$F$695,6,0),"") -> 0.00988 | R38: =IFERROR(Q38*P38,0) -> 0.78913536 | S38: =R38*10% -> 0.078913536 | T38: =R38+S38 -> 0.8680489 | U38: =T38*10% -> 0.08680489 | V38: =T38*1% -> 0.008680489 | W38: =T38*1% -> 0.008680489 | X38: =T38+U38+V38+W38 -> 0.97221476
A39: RCP-Frsh-00002 | B39: Plates | C39: Frsh | D39: Spinach steak | E39: Saturday | F39: Hot Section | G39: Spinach Sauce | H39: =IFERROR(VLOOKUP(I39,'Raw material list'!$A$3:$C$695,3,0),"") -> DRS1-114 | I39: Sea Salt(737 Gram) | J39: Gram | K39: =IFERROR(VLOOKUP(I39,'Raw material list'!$A$3:$E$695,5,0),"") -> Gram | L39: 3.99 | M39: =L39/N39*100 -> 3.99 | N39: 100 | O39: 10 | P39: =IFERROR(L39/O39,0) -> 0.399 | Q39: =IFERROR(VLOOKUP(I39,'Raw material list'!$A$3:$F$695,6,0),"") -> 0.0047489824 | R39: =IFERROR(Q39*P39,0) -> 0.001894844 | S39: =R39*10% -> 0.0001894844 | T39: =R39+S39 -> 0.0020843284 | U39: =T39*10% -> 0.00020843284 | V39: =T39*1% -> 2.0843284e-05 | W39: =T39*1% -> 2.0843284e-05 | X39: =T39+U39+V39+W39 -> 0.0023344478
A40: RCP-Frsh-00002 | B40: Plates | C40: Frsh | D40: Spinach steak | E40: Saturday | F40: Hot Section | G40: Spinach Sauce | H40: =IFERROR(VLOOKUP(I40,'Raw material list'!$A$3:$C$695,3,0),"") -> DRS6-537 | I40: Spices Pepper Black Powder(1 Kg) | J40: Gram | K40: =IFERROR(VLOOKUP(I40,'Raw material list'!$A$3:$E$695,5,0),"") -> Gram | L40: 2.39 | M40: =L40/N40*100 -> 2.39 | N40: 100 | O40: 10 | P40: =IFERROR(L40/O40,0) -> 0.239 | Q40: =IFERROR(VLOOKUP(I40,'Raw material list'!$A$3:$F$695,6,0),"") -> 0.035 | R40: =IFERROR(Q40*P40,0) -> 0.008365 | S40: =R40*10% -> 0.0008365 | T40: =R40+S40 -> 0.0092015 | U40: =T40*10% -> 0.00092015 | V40: =T40*1% -> 9.2015e-05 | W40: =T40*1% -> 9.2015e-05 | X40: =T40+U40+V40+W40 -> 0.01030568
A41: RCP-Frsh-00002 | B41: Plates | C41: Frsh | D41: Spinach steak | E41: Saturday | F41: Hot Section | G41: Spinach Sauce | H41: =IFERROR(VLOOKUP(I41,'Raw material list'!$A$3:$C$695,3,0),"") -> PRD1-209 | I41: Fresh Lemon | J41: Gram | K41: =IFERROR(VLOOKUP(I41,'Raw material list'!$A$3:$E$695,5,0),"") -> Gram | L41: 3.19 | M41: =L41/N41*100 -> 8.3947368 | N41: 38 | O41: 10 | P41: =IFERROR(L41/O41,0) -> 0.319 | Q41: =IFERROR(VLOOKUP(I41,'Raw material list'!$A$3:$F$695,6,0),"") -> 0.010088272 | R41: =IFERROR(Q41*P41,0) -> 0.0032181589 | S41: =R41*10% -> 0.00032181589 | T41: =R41+S41 -> 0.0035399748 | U41: =T41*10% -> 0.00035399748 | V41: =T41*1% -> 3.5399748e-05 | W41: =T41*1% -> 3.5399748e-05 | X41: =T41+U41+V41+W41 -> 0.0039647718
...

Sheet Raw material list
C1: Master Raw Material
A2: Items Description | C2: Code | D2: NameEN | E2: Unit | F2: Price | G2: Main category | H2: Sub category
A3: Bran Bread Brown (Diet) | C3: BKR1-1917 | D3: Bran Bread Brown (Diet) | E3: Each | F3: 0.95 | G3: Fresh | H3: Bakery
A4: Bread Arabic Brown (6 each) 400211 | C4: BKR1-3695 | D4: Bread Arabic Brown (6 each) 400211 | E4: Each | F4: 0.16666667 | G4: Fresh | H4: Bakery
A5: Bread Arabic White(7 Each) 400210 | C5: BKR1-3694 | D5: Bread Arabic White(7 Each) 400210 | E5: Each | F5: 0.14285714 | G5: Fresh | H5: Bakery
A6: Bread Burger Bun Brown(Each) | C6: BKR1-3791 | D6: Bread Burger Bun Brown(Each) | E6: Each | F6: 1 | G6: Fresh | H6: Bakery
A7: Bread Crumb IMP(Packet) | C7: BKR1-4011 | D7: Bread Crumb IMP(Packet) | E7: Gram | F7: 0.022 | G7: Fresh | H7: Bakery
A8: Bread Jumbo Sandwich White 400007 | C8: BKR1-1328 | D8: Bread Jumbo Sandwich White 400007 | E8: Each | F8: 1 | G8: Fresh | H8: Bakery
A9: Bread Potato Burger Plain | C9: BKR1-4332 | D9: Bread Potato Burger Plain | E9: Each | F9: 0.55833333 | G9: Fresh | H9: Bakery
A10: Spices Bay Leaves | C10: DRS6-3593 | D10: Bay Leaf | E10: Gram | F10: 0.0105 | G10: Dry
A11: Bread Shawarma | C11: BKR1-1575 | D11: Bread Shawarma | E11: Each | F11: 0.12 | G11: Fresh | H11: Bakery
A12: Bread Sliced Brown Med-400001 | C12: BKR1-1327 | D12: Bread Sliced Brown Med-400001 | E12: Slice | F12: 0.22222222 | G12: Fresh | H12: Bakery
A13: Bread Sliced White Med-400000 | C13: BKR1-1326 | D13: Bread Sliced White Med-400000 | E13: Slice | F13: 0.16666667 | G13: Fresh | H13: Bakery
A14: Fresh Bread Baguette Long Brown | C14: BKR1-3428 | D14: Fresh Bread Baguette Long Brown | E14: Each | F14: 4.78 | G14: Fresh | H14: Bakery
A15: Sriracha hot sauce | C15: DRS1-4954 | D15: Sriracha hot sauce | E15: ML | F15: 0.029
A16: Frz Kunafa Dough | C16: BKR1-1910 | D16: Frz Kunafa Dough | E16: Gram | F16: 0.01366 | G16: Frozen | H16: Bakery
A17: Milk Bread Mini 9Pcs | C17: BKR1-2125 | D17: Milk Bread Mini 9Pcs | E17: Each | F17: 0.44444444 | G17: Fresh | H17: Bakery
A18: Tang mango | C18: DRS1-4905 | D18: Tang mango | E18: Gram | F18: 0.0208
A19: Tang orange | C19: DRS1-4902 | D19: Tang orange | E19: Gram | F19: 0.0208
A20: Qursan | C20: BKR1-4717 | D20: Qursan | E20: Gram | F20: 0.013 | G20: Fresh | H20: Bakery
A21: Tart Shell Round Mini 3.7 Cm,Sweet | C21: BKR1-4132 | D21: Tart Shell Round Mini 3.7 Cm,Sweet | E21: Each | F21: 0.84126984 | G21: Fresh | H21: Bakery
A22: Bread Tortilla White,20cm(Fonte) | C22: BKR2-4274 | D22: Bread Tortilla White,20cm(Fonte) | E22: Each | F22: 0.625 | G22: Frozen | H22: Bakery
A23: Bread Tortilla White,30cm(Fonte) | C23: BKR2-4275 | D23: Bread Tortilla White,30cm(Fonte) | E23: Each | F23: 0.83333333 | G23: Frozen | H23: Bakery
A24: Frz Bread Baguette French (40080009) | C24: BKR2-2058 | D24: Frz Bread Baguette French (40080009) | E24: Gram | F24: 0.0066666667 | G24: Frozen | H24: Bakery
A25: Frz Bread Baguette Multicereal (40080109) | C25: BKR2-2059 | D25: Frz Bread Baguette Multicereal (40080109) | E25: Gram | F25: 0.01 | G25: Frozen | H25: Bakery
A26: Frz Bread Jumbo Sandwich 400017 | C26: BKR2-5081 | D26: Frz Bread Jumbo Sandwich 400017 | E26: Each | F26: 0.96666667 | G26: Frozen | H26: Bakery
A27: Frz Bread Panini (90 Gram) | C27: BKR2-4596 | D27: Frz Bread Panini (90 Gram) | E27: Each | F27: 0.96 | G27: Frozen | H27: Bakery
A28: Frz Bread Tortilla,Keto,8 Inch | C28: BKR2-4961 | D28: Frz Bread Tortilla,Keto,8 Inch | E28: Each | F28: 3 | G28: Frozen | H28: Bakery
A29: Frz Sambusak Leaves (1 kg) | C29: BKR2-5137 | D29: Frz Sambusak Leaves (1 kg) | E29: Gram | F29: 0.01413 | G29: Frozen | H29: Bakery
A30: Frz Spring Roll Dough(160 Gram) | C30: BKR2-1104 | D30: Frz Spring Roll Dough(160 Gram) | E30: Gram | F30: 0.0255 | G30: Frozen | H30: Bakery
A31: Frz.Puff Pastry Sheets(400Gram) | C31: BKR2-3658 | D31: Frz.Puff Pastry Sheets(400Gram) | E31: Gram | F31: 0.019175 | G31: Frozen | H31: Bakery
A32: Jam Apricot Portion(100 Each) | C32: DRS1-5003 | D32: Jam Apricot Portion(100 Each) | E32: Each | F32: 0.38 | G32: Dry | H32: Canned Item
A33: Italian seasoning | C33: DRS6-5020 | D33: Italian seasoning | E33: Gram | F33: 0.15
A34: Cinnamon Stick | C34: DRS6-261 | D34: Cinnamon Stick | E34: Gram | F34: 0.014 | G34: Dry | H34: Spices
A35: Light Mayonnaise | C35: DRS1-1652 | D35: Light Mayonnaise | E35: Gram | F35: 0.0128
A36: Ajinomoto (MSG) 454 gm | C36: DRS1-5155 | D36: Ajinomoto (MSG) 454 gm | E36: Gram | F36: 0.019823789 | G36: Dry | H36: Canned Item
A37: Apple Vinegar | C37: DRS1-4227 | D37: Apple Vinegar | E37: Ml | F37: 0.0058139535 | G37: Dry | H37: Canned Item
A38: Beef Stock Powder(Packet) | C38: DRS1-3813 | D38: Beef Stock Powder(Packet) | E38: Gram | F38: 0.044441667 | G38: Dry | H38: Canned Item
A39: Biscuit Digestive (150 Gram) | C39: DRS1-3696 | D39: Biscuit Digestive (150 Gram) | E39: Gram | F39: 0.0094666667 | G39: Dry | H39: Canned Item
A40: Butter Peanuts(794 Gram) | C40: DRS1-4103 | D40: Butter Peanuts(794 Gram) | E40: Gram | F40: 0.026763224 | G40: Dry | H40: Canned Item
...
