Workbook

Sheet Menu
A1: SMC Inpatient Menu
A2: BREAKFAST & LUNCH & DINNER INPATIENTS MENU 2026
A4: Days | B4: Recipe Code | C4: Recipe Name | D4: Category | E4: Meal Order | F4: DIET TYPE
A5: Saturday | B5: ='Master – Recipes'!A161 -> RCP-SMC-000158 | C5: Croissant Cheese and Foul Meddames | D5: Main Course Breakfast | E5: BREAKFAST | F5: RD
A6: Saturday | B6: ='Master – Recipes'!A162 -> RCP-SMC-000159 | C6: Foul and Labneh | D6: Main Course Breakfast | E6: BREAKFAST | F6: DM/ CARDIAC
A7: Saturday | B7: ='Master – Recipes'!A163 -> RCP-SMC-000160 | C7: Labneh and Boiled Egg | D7: Main Course Breakfast | E7: BREAKFAST | F7: RENAL
A8: Saturday | B8: ='Master – Recipes'!A164 -> RCP-SMC-000161 | C8: Boiled Egg 1 Pcs and Foul | D8: Main Course Breakfast | E8: BREAKFAST | F8: DM/ CARDIAC
A9: Saturday | B9: ='Master – Recipes'!A165 -> RCP-SMC-000162 | C9: (Soft Diet) Fruits Pudding and Boiled egg | D9: Main Course Breakfast | E9: BREAKFAST | F9: SD
A10: Saturday | B10: ='Master – Recipes'!A131 -> RCP-SMC-000128 | C10: Sliced Vegetables with Olives | D10: Side Items Breakfast | E10: BREAKFAST | F10: RD/ DM / CARDIAC
A11: Saturday | B11: ='Master – Recipes'!A135 -> RCP-SMC-000132 | C11: TEA SET PACKET | D11: Side Items Breakfast | E11: BREAKFAST | F11: ALL DIETS
A12: Saturday | B12: ='Master – Recipes'!A121 -> RCP-SMC-000118 | C12: Turkish Red Lentil Soup | D12: Soup | E12: LUNCH | F12: REGULAR DIET / DIABETIC DIET
A13: Saturday | B13: ='Master – Recipes'!A123 -> RCP-SMC-000120 | C13: Cream of Chicken Soup | D13: Soup | E13: LUNCH | F13: REGULAR DIET / DIABETIC DIET
A14: Saturday | B14: ='Master – Recipes'!A88 -> RCP-SMC-000086 | C14: Clear Soup | D14: Soup | E14: LUNCH | F14: CLEAR LIQUID DIET
A15: Saturday | B15: ='Master – Recipes'!A122 -> RCP-SMC-000119 | C15: Strained Cream of Chicken Soup | D15: Soup | E15: LUNCH | F15: SOFT DIET
A16: Saturday | B16: ='Master – Recipes'!A160 -> RCP-SMC-000157 | C16: GREEK SALAD With Lemon Dressing | D16: Salad | E16: LUNCH | F16: REGULAR DIET / DIABETIC DIET
A17: Saturday | B17: ='Master – Recipes'!A152 -> RCP-SMC-000149 | C17: SPECIAL DIET SALAD ( Lettuce, peeled cucumber and Shredded Carrots ) | D17: Salad | E17: LUNCH | F17: SOFT DIET
A18: Saturday | B18: ='Master – Recipes'!A53 -> RCP-SMC-000054 | C18: Chicken Butter Sauce With White Rice | D18: Main Course - Lunch | E18: LUNCH | F18: REGULAR DIET / DIABETIC DIET
A19: Saturday | B19: ='Master – Recipes'!A16 -> RCP-SMC-000020 | C19: Seafood/Fish Sayadeya with Tahina Sauce | D19: Main Course - Lunch | E19: LUNCH | F19: REGULAR DIET / DIABETIC DIET
A20: Saturday | B20: ='Master – Recipes'!A52 -> RCP-SMC-000053 | C20: Beef Spaghetti Bolognese | D20: Main Course - Lunch | E20: LUNCH | F20: REGULAR DIET / DIABETIC DIET
A21: Saturday | B21: ='Master – Recipes'!A63 -> RCP-SMC-000063 | C21: Chicken Curry with White Rice | D21: Daily Main Course - Lunch | E21: LUNCH | F21: REGULAR DIET / DIABETIC DIET
A22: Saturday | B22: ='Master – Recipes'!A71 -> RCP-SMC-000070 | C22: Boiled Chicken with Soft Rice/ Boiled potato and Boiled Vegetables | D22: Daily Main Course - Lunch | E22: LUNCH | F22: ANTI D DIET
A23: Saturday | B23: ='Master – Recipes'!A61 -> RCP-SMC-000061 | C23: low sodium low Seasoning Grilled Chicken Breast with white Rice, Sauteed Mixed Veggies & Vegetarian Edam Cut Beans stew | D23: Daily Main Course - Lunch | E23: LUNCH | F23: CARDIAC DIET
A24: Saturday | B24: =B50 -> RCP-SMC-000071 | C24: low sodium low Seasoning Grilled Fish with White Rice & Vegetable Sauté | D24: Daily Main Course - Lunch | E24: LUNCH | F24: RENAL DIET
A25: Saturday | B25: =B51 -> RCP-SMC-000068 | C25: Chicken Kabssa With Dakkous Sauce | D25: Daily Main Course - Lunch | E25: LUNCH | F25: REGULAR DIET / DIABETIC DIET
A26: Saturday | B26: ='Master – Recipes'!A51 -> RCP-SMC-000052 | C26: Chicken Adobo W/ Potato and Soft Rice | D26: Daily Main Course - Lunch | E26: LUNCH | F26: REGULAR DIET / DIABETIC DIET
A27: Saturday | B27: ='Master – Recipes'!A64 -> RCP-SMC-000064 | C27: Cream Chicken Pasta and Mashed Vegetables | D27: Daily Main Course - Lunch | E27: LUNCH | F27: SOFT DIET
A28: Saturday | B28: =B77 -> RCP-SMC-000062 | C28: Soft Diet- beef White Jareesh Healthy Style with Mashed Vegetables | D28: Daily Main Course - Lunch | E28: LUNCH | F28: SOFT DIET
A29: Saturday | B29: ='Master – Recipes'!A67 -> RCP-SMC-000067 | C29: Puree Lunch (Chicken and Vegetables) | D29: Daily Main Course - Lunch | E29: LUNCH | F29: PUREE DIET
A30: Saturday | B30: ='Master – Recipes'!A78 -> RCP-SMC-000077 | C30: Seasonal Fresh Sliced Fruits | D30: Dessert | E30: LUNCH | F30: REGULAR DIET
A31: Saturday | B31: ='Master – Recipes'!A79 -> RCP-SMC-000078 | C31: Seasonal Fresh VIP Fruits | D31: Dessert | E31: LUNCH | F31: REGULAR DIET
A32: Saturday | B32: ='Master – Recipes'!A84 -> RCP-SMC-000082 | C32: Marble English Cake | D32: Dessert | E32: LUNCH | F32: REGULAR DIET
A33: Saturday | B33: ='Master – Recipes'!A86 -> RCP-SMC-000084 | C33: Sweet of The Day | D33: Dessert | E33: LUNCH | F33: REGULAR DIET
A34: Saturday | B34: ='Master – Recipes'!A74 -> RCP-SMC-000073 | C34: Regular Mohalabeya | D34: Dessert | E34: LUNCH | F34: SOFT DIET
A35: Saturday | B35: ='Master – Recipes'!A75 -> RCP-SMC-000074 | C35: Diabetic Mohalabeya | D35: Dessert | E35: LUNCH | F35: DIABETIC DIET
A36: Saturday | B36: ='Master – Recipes'!A76 -> RCP-SMC-000075 | C36: Jello | D36: Dessert | E36: LUNCH | F36: CLEAR LIQUID DIET
A37: Saturday | B37: ='Master – Recipes'!A77 -> RCP-SMC-000076 | C37: Custard | D37: Dessert | E37: LUNCH | F37: SOFT DIET
A38: Saturday | B38: ='Master – Recipes'!A120 -> RCP-SMC-000117 | C38: Crème of Leeks & Potato | D38: Soup | E38: DINNER | F38: REGULAR DIET / DIABETIC DIET/ SOFT
A39: Saturday | B39: ='Master – Recipes'!A119 -> RCP-SMC-000116 | C39: Chicken Ministrone Soup | D39: Soup | E39: DINNER | F39: REGULAR DIET / DIABETIC DIET
A40: Saturday | B40: =B14 -> RCP-SMC-000086 | C40: Clear Soup | D40: Soup | E40: DINNER | F40: CLEAR LIQUID DIET
A41: Saturday | B41: ='Master – Recipes'!A153 -> RCP-SMC-000150 | C41: Cucumber Yogurt Salad | D41: Salad | E41: DINNER | F41: REGULAR DIET / DIABETIC DIET
...

Sheet Sheet2
A3: Recipe Ref | B3: Customer Name | C3: Recipe Name | D3: Days | E3: Category | F3: Sum of Qty req per Batch (g/pcs) | G3: Max of No. of portions per batch | H3: Sum of Food Cost per portion
A4: RCP-SMC-00001 | B4: SMC | C4: Thai shrimp curry with white rice | D4: Sunday | E4: Main Course | F4: 5725 | G4: 10 | H4: 9.8937403
A5: RCP-SMC-000010 | B5: SMC | C5: Halloumi Panini pesto sandwich | D5: Monday | E5: Main Course | F5: 414 | G5: 4 | H5: 4.3622314
A6: RCP-SMC-000011 | B6: SMC | C6: Beef vegetable qursan | D6: Monday | E6: Main Course | F6: 4885 | G6: 10 | H6: 9.0984588
A7: RCP-SMC-000012 | B7: SMC | C7: chicken mandi with dokus sause | D7: Monday | E7: Main Course | F7: 6528 | G7: 10 | H7: 5.1434832
A8: RCP-SMC-000013 | B8: SMC | C8: Low Sodium Chicken Breast - Vegetables | D8: Monday | E8: Main Course | F8: 6195 | G8: 10 | H8: 5.4269713
A9: RCP-SMC-000014 | B9: SMC | C9: Koshari with crispy onion spicy tomato | D9: Monday | E9: Main Course | F9: 2736 | G9: 10 | H9: 2.8563074
A10: RCP-SMC-000015 | B10: SMC | C10: Veal with Red Burgul lebanese Style | D10: Monday | E10: Main Course | F10: 5158 | G10: 10 | H10: 10.275901
A11: RCP-SMC-000016 | B11: SMC | C11: Kofta with potato,egyplant | D11: Monday | E11: Main Course | F11: 7324 | G11: 10 | H11: 6.6770473
A12: RCP-SMC-000017 | B12: SMC | C12: Chicken Afritada w Soft Rice | D12: Monday | E12: Main Course | F12: 8080 | G12: 10 | H12: 6.767742
A13: RCP-SMC-000018 | B13: SMC | C13: Beef Burger | D13: Tuesday | E13: Main Course | F13: 2972.5 | G13: 10 | H13: 5.8759257
A14: RCP-SMC-000019 | B14: SMC | C14: Chicken sweet and sour | D14: Tuesday | E14: Main Course | F14: 5989 | G14: 10 | H14: 5.0505764
A15: RCP-SMC-00002 | B15: SMC | C15: kebbeh labnieh with vermicelli rice | D15: Sunday | E15: Main Course | F15: 6267 | G15: 10 | H15: 6.2906322
... A160: RCP-SMC-000157 | B160: SMC | C160: Greek Salad With Lemon | D160: Saturday | E160: Salad | F160: 156 | G160: 1 | H160: 1.8045202
A161: (blank) | B161: (blank) | C161: (blank) | D161: (blank) | E161: (blank)
A162: Grand Total | F162: 1127361.7 | G162: 900 | H162: 478.02769

Sheet Master – Recipes
A1: 📘 Master – Recipes-SMC
A3: Recipe Ref | B3: Customer Name | C3: Recipe Name | D3: Days | E3: Category | F3: Sum of Qty req per Batch (g/pcs) | G3: Max of No. of portions per batch | H3: Sum of Food Cost per portion | I3: Variable Food Cost 10% | J3: Total Food Cost | K3: Packaging Cost | L3: Labor Cost | M3: Delivery Cost | N3: Overheads | O3: Other Costs | P3: Total Cost | Q3: Labour Cost | R3: Packing Cost | S3: Delivery Cost | T3: Other veriables cost | U3: Total Cost
A4: RCP-SMC-00001 | B4: SMC | C4: Thai shrimp curry with white rice | D4: Sunday | E4: Main Course | F4: 5725 | G4: 10 | H4: 9.8937403 | I4: =H4*10% -> 0.98937403 | J4: =H4+I4 -> 10.883114 | O4: =SUM(H4:N4) -> 21.766229 | Q4: =J4*5% -> 0.54415572 | R4: =J4*2% -> 0.21766229 | S4: =J4*2% -> 0.21766229 | T4: =J4*1% -> 0.10883114 | U4: =J4+Q4+R4+S4+T4 -> 11.971426 | V4: LC,PC,DC,OVC % are only Assumed
A5: RCP-SMC-000010 | B5: SMC | C5: Halloumi Panini pesto sandwich | D5: Monday | E5: Main Course | F5: 414 | G5: 4 | H5: 4.3622314 | I5: =H5*10% -> 0.43622314 | J5: =H5+I5 -> 4.7984545 | O5: =SUM(H5:N5) -> 9.5969091 | Q5: =J5*5% -> 0.23992273 | R5: =J5*2% -> 0.095969091 | S5: =J5*2% -> 0.095969091 | T5: =J5*1% -> 0.047984545 | U5: =J5+Q5+R5+S5+T5 -> 5.2783
A6: RCP-SMC-000011 | B6: SMC | C6: Beef vegetable qursan | D6: Monday | E6: Main Course | F6: 4885 | G6: 10 | H6: 9.0984588 | I6: =H6*10% -> 0.90984588 | J6: =H6+I6 -> 10.008305 | O6: =SUM(H6:N6) -> 20.016609 | Q6: =J6*5% -> 0.50041524 | R6: =J6*2% -> 0.20016609 | S6: =J6*2% -> 0.20016609 | T6: =J6*1% -> 0.10008305 | U6: =J6+Q6+R6+S6+T6 -> 11.009135
A7: RCP-SMC-000012 | B7: SMC | C7: chicken mandi with dokus sause | D7: Monday | E7: Main Course | F7: 6528 | G7: 10 | H7: 5.1434832 | I7: =H7*10% -> 0.51434832 | J7: =H7+I7 -> 5.6578315 | O7: =SUM(H7:N7) -> 11.315663 | Q7: =J7*5% -> 0.28289157 | R7: =J7*2% -> 0.11315663 | S7: =J7*2% -> 0.11315663 | T7: =J7*1% -> 0.056578315 | U7: =J7+Q7+R7+S7+T7 -> 6.2236146
A8: RCP-SMC-000013 | B8: SMC | C8: Low Sodium Chicken Breast - Vegetables | D8: Monday | E8: Main Course | F8: 6195 | G8: 10 | H8: 5.4269713 | I8: =H8*10% -> 0.54269713 | J8: =H8+I8 -> 5.9696684 | O8: =SUM(H8:N8) -> 11.939337 | Q8: =J8*5% -> 0.29848342 | R8: =J8*2% -> 0.11939337 | S8: =J8*2% -> 0.11939337 | T8: =J8*1% -> 0.059696684 | U8: =J8+Q8+R8+S8+T8 -> 6.5666352
A9: RCP-SMC-000014 | B9: SMC | C9: Koshari with crispy onion spicy tomato | D9: Monday | E9: Main Course | F9: 2736 | G9: 10 | H9: 2.8563074 | I9: =H9*10% -> 0.28563074 | J9: =H9+I9 -> 3.1419381 | O9: =SUM(H9:N9) -> 6.2838763 | Q9: =J9*5% -> 0.15709691 | R9: =J9*2% -> 0.062838763 | S9: =J9*2% -> 0.062838763 | T9: =J9*1% -> 0.031419381 | U9: =J9+Q9+R9+S9+T9 -> 3.456132
A10: RCP-SMC-000015 | B10: SMC | C10: Veal with Red Burgul lebanese Style | D10: Monday | E10: Main Course | F10: 5158 | G10: 10 | H10: 10.275901 | I10: =H10*10% -> 1.0275901 | J10: =H10+I10 -> 11.303491 | O10: =SUM(H10:N10) -> 22.606983 | Q10: =J10*5% -> 0.56517457 | R10: =J10*2% -> 0.22606983 | S10: =J10*2% -> 0.22606983 | T10: =J10*1% -> 0.11303491 | U10: =J10+Q10+R10+S10+T10 -> 12.433841
A11: RCP-SMC-000016 | B11: SMC | C11: Kofta with potato,egyplant | D11: Monday | E11: Main Course | F11: 7324 | G11: 10 | H11: 6.6770473 | I11: =H11*10% -> 0.66770473 | J11: =H11+I11 -> 7.344752 | O11: =SUM(H11:N11) -> 14.689504 | Q11: =J11*5% -> 0.3672376 | R11: =J11*2% -> 0.14689504 | S11: =J11*2% -> 0.14689504 | T11: =J11*1% -> 0.07344752 | U11: =J11+Q11+R11+S11+T11 -> 8.0792272
A12: RCP-SMC-000017 | B12: SMC | C12: Chicken Afritada w Soft Rice | D12: Monday | E12: Main Course | F12: 8080 | G12: 10 | H12: 6.767742 | I12: =H12*10% -> 0.6767742 | J12: =H12+I12 -> 7.4445162 | O12: =SUM(H12:N12) -> 14.889032 | Q12: =J12*5% -> 0.37222581 | R12: =J12*2% -> 0.14889032 | S12: =J12*2% -> 0.14889032 | T12: =J12*1% -> 0.074445162 | U12: =J12+Q12+R12+S12+T12 -> 8.1889678
A13: RCP-SMC-000018 | B13: SMC | C13: Beef Burger | D13: Tuesday | E13: Main Course | F13: 2972.5 | G13: 10 | H13: 5.8759257 | I13: =H13*10% -> 0.58759257 | J13: =H13+I13 -> 6.4635182 | O13: =SUM(H13:N13) -> 12.927036 | Q13: =J13*5% -> 0.32317591 | R13: =J13*2% -> 0.12927036 | S13: =J13*2% -> 0.12927036 | T13: =J13*1% -> 0.064635182 | U13: =J13+Q13+R13+S13+T13 -> 7.1098701
A14: RCP-SMC-000019 | B14: SMC | C14: Chicken sweet and sour | D14: Tuesday | E14: Main Course | F14: 5989 | G14: 10 | H14: 5.0505764 | I14: =H14*10% -> 0.50505764 | J14: =H14+I14 -> 5.555634 | O14: =SUM(H14:N14) -> 11.111268 | Q14: =J14*5% -> 0.2777817 | R14: =J14*2% -> 0.11111268 | S14: =J14*2% -> 0.11111268 | T14: =J14*1% -> 0.05555634 | U14: =J14+Q14+R14+S14+T14 -> 6.1111974
A15: RCP-SMC-00002 | B15: SMC | C15: kebbeh labnieh with vermicelli rice | D15: Sunday | E15: Main Course | F15: 6267 | G15: 10 | H15: 6.2906322 | I15: =H15*10% -> 0.62906322 | J15: =H15+I15 -> 6.9196954 | O15: =SUM(H15:N15) -> 13.839391 | Q15: =J15*5% -> 0.34598477 | R15: =J15*2% -> 0.13839391 | S15: =J15*2% -> 0.13839391 | T15: =J15*1% -> 0.069196954 | U15: =J15+Q15+R15+S15+T15 -> 7.6116649
A16: RCP-SMC-000020 | B16: SMC | C16: Fish Sayadiah with Brown Rice & Tahina Sauce | D16: Tuesday | E16: Main Course | F16: 4692 | G16: 10 | H16: 4.6654383 | I16: =H16*10% -> 0.46654383 | J16: =H16+I16 -> 5.1319822 | O16: =SUM(H16:N16) -> 10.263964 | Q16: =J16*5% -> 0.25659911 | R16: =J16*2% -> 0.10263964 | S16: =J16*2% -> 0.10263964 | T16: =J16*1% -> 0.051319822 | U16: =J16+Q16+R16+S16+T16 -> 5.6451804
... A160: RCP-SMC-000157 | B160: SMC | C160: Greek Salad With Lemon | D160: Saturday | E160: Salad | F160: 156 | G160: 1 | H160: 1.8045202 | I160: =H160*10% -> 0.18045202 | J160: =H160+I160 -> 1.9849722 | O160: =SUM(H160:N160) -> 3.9699445 | Q160: =J160*5% -> 0.099248612 | R160: =J160*2% -> 0.039699445 | S160: =J160*2% -> 0.039699445 | T160: =J160*1% -> 0.019849722 | U160: =J160+Q160+R160+S160+T160 -> 2.1834695
A161: RCP-SMC-000158 | B161: SMC | C161: Croissant Cheese and Foul Meddames | D161: Saturday | E161: Breakfast | F161: =SUMIF('Recipe Ingredients'!$A$5:$A$2237,'Master – Recipes'!A161,'Recipe Ingredients'!$O$5:$O$2237) -> 69660 | H161: =SUMIF('Recipe Ingredients'!$A$5:$A$2237,'Master – Recipes'!A161,'Recipe Ingredients'!$W$5:$W$2238) -> 1.4586544 | I161: =H161*10% -> 0.14586544 | J161: =H161+I161 -> 1.6045199 | Q161: =J161*5% -> 0.080225994 | R161: =J161*2% -> 0.032090398 | S161: =J161*2% -> 0.032090398 | T161: =J161*1% -> 0.016045199 | U161: =J161+Q161+R161+S161+T161 -> 1.7649719
A162: RCP-SMC-000159 | B162: SMC | C162: Foul and Labneh | E162: Breakfast | F162: =SUMIF('Recipe Ingredients'!$A$5:$A$2237,'Master – Recipes'!A162,'Recipe Ingredients'!$O$5:$O$2237) -> 3075.25 | H162: =SUMIF('Recipe Ingredients'!$A$5:$A$2237,'Master – Recipes'!A162,'Recipe Ingredients'!$W$5:$W$2238) -> 2.2021946 | I162: =H162*10% -> 0.22021946 | J162: =H162+I162 -> 2.422414 | Q162: =J162*5% -> 0.1211207 | R162: =J162*2% -> 0.048448281 | S162: =J162*2% -> 0.048448281 | T162: =J162*1% -> 0.02422414 | U162: =J162+Q162+R162+S162+T162 -> 2.6646555
A163: RCP-SMC-000160 | B163: SMC | C163: Labneh and Boiled Egg | E163: Breakfast | F163: =SUMIF('Recipe Ingredients'!$A$5:$A$2237,'Master – Recipes'!A163,'Recipe Ingredients'!$O$5:$O$2237) -> 336.25 | H163: =SUMIF('Recipe Ingredients'!$A$5:$A$2237,'Master – Recipes'!A163,'Recipe Ingredients'!$W$5:$W$2238) -> 1.8396635 | I163: =H163*10% -> 0.18396635 | J163: =H163+I163 -> 2.0236299 | Q163: =J163*5% -> 0.10118149 | R163: =J163*2% -> 0.040472598 | S163: =J163*2% -> 0.040472598 | T163: =J163*1% -> 0.020236299 | U163: =J163+Q163+R163+S163+T163 -> 2.2259929
A164: RCP-SMC-000161 | B164: SMC | C164: Boiled Egg 1 Pcs and Foul | E164: Breakfast | F164: =SUMIF('Recipe Ingredients'!$A$5:$A$2237,'Master – Recipes'!A164,'Recipe Ingredients'!$O$5:$O$2237) -> 3201 | H164: =SUMIF('Recipe Ingredients'!$A$5:$A$2237,'Master – Recipes'!A164,'Recipe Ingredients'!$W$5:$W$2238) -> 1.4626363 | I164: =H164*10% -> 0.14626363 | J164: =H164+I164 -> 1.6089 | Q164: =J164*5% -> 0.080444998 | R164: =J164*2% -> 0.032177999 | S164: =J164*2% -> 0.032177999 | T164: =J164*1% -> 0.016089 | U164: =J164+Q164+R164+S164+T164 -> 1.76979
A165: RCP-SMC-000162 | B165: SMC | C165: (Soft Diet) Fruits Pudding and Boiled egg | E165: Breakfast | F165: =SUMIF('Recipe Ingredients'!$A$5:$A$2237,'Master – Recipes'!A165,'Recipe Ingredients'!$O$5:$O$2237) -> 3623 | H165: =SUMIF('Recipe Ingredients'!$A$5:$A$2237,'Master – Recipes'!A165,'Recipe Ingredients'!$W$5:$W$2238) -> 1.852826 | I165: =H165*10% -> 0.1852826 | J165: =H165+I165 -> 2.0381086 | Q165: =J165*5% -> 0.10190543 | R165: =J165*2% -> 0.040762171 | S165: =J165*2% -> 0.040762171 | T165: =J165*1% -> 0.020381086 | U165: =J165+Q165+R165+S165+T165 -> 2.2419194
A166: RCP-SMC-000163 | B166: SMC | C166: Danish Pastry and Shaksouka | D166: Sunday | E166: Breakfast | F166: =SUMIF('Recipe Ingredients'!$A$5:$A$2237,'Master – Recipes'!A166,'Recipe Ingredients'!$O$5:$O$2237) -> 95990 | H166: =SUMIF('Recipe Ingredients'!$A$5:$A$2237,'Master – Recipes'!A166,'Recipe Ingredients'!$W$5:$W$2238) -> 2.9161797 | I166: =H166*10% -> 0.29161797 | J166: =H166+I166 -> 3.2077977 | Q166: =J166*5% -> 0.16038989 | R166: =J166*2% -> 0.064155954 | S166: =J166*2% -> 0.064155954 | T166: =J166*1% -> 0.032077977 | U166: =J166+Q166+R166+S166+T166 -> 3.5285775
A167: RCP-SMC-000164 | B167: SMC | C167: (Soft Diet) Oats Pudding and Labneh | E167: Breakfast | F167: =SUMIF('Recipe Ingredients'!$A$5:$A$2237,'Master – Recipes'!A167,'Recipe Ingredients'!$O$5:$O$2237) -> 3497.25 | H167: =SUMIF('Recipe Ingredients'!$A$5:$A$2237,'Master – Recipes'!A167,'Recipe Ingredients'!$W$5:$W$2238) -> 2.5923842 | I167: =H167*10% -> 0.25923842 | J167: =H167+I167 -> 2.8516227 | Q167: =J167*5% -> 0.14258113 | R167: =J167*2% -> 0.057032453 | S167: =J167*2% -> 0.057032453 | T167: =J167*1% -> 0.028516227 | U167: =J167+Q167+R167+S167+T167 -> 3.1367849
A168: RCP-SMC-000165 | B168: SMC | C168: Foul Gulaba and Halwa Tahiniah (60 Gram) | D168: Monday | E168: Breakfast | F168: =SUMIF('Recipe Ingredients'!$A$5:$A$2237,'Master – Recipes'!A168,'Recipe Ingredients'!$O$5:$O$2237) -> 2890 | H168: =SUMIF('Recipe Ingredients'!$A$5:$A$2237,'Master – Recipes'!A168,'Recipe Ingredients'!$W$5:$W$2238) -> 1.3065837 | I168: =H168*10% -> 0.13065837 | J168: =H168+I168 -> 1.4372421 | Q168: =J168*5% -> 0.071862103 | R168: =J168*2% -> 0.028744841 | S168: =J168*2% -> 0.028744841 | T168: =J168*1% -> 0.014372421 | U168: =J168+Q168+R168+S168+T168 -> 1.5809663
A169: RCP-SMC-000166 | B169: SMC | C169: Chicken Manakish and Labneh | D169: Tuesday | E169: Breakfast | F169: =SUMIF('Recipe Ingredients'!$A$5:$A$2237,'Master – Recipes'!A169,'Recipe Ingredients'!$O$5:$O$2237) -> 4356.25 | H169: =SUMIF('Recipe Ingredients'!$A$5:$A$2237,'Master – Recipes'!A169,'Recipe Ingredients'!$W$5:$W$2238) -> 2.6958123 | I169: =H169*10% -> 0.26958123 | J169: =H169+I169 -> 2.9653936 | Q169: =J169*5% -> 0.14826968 | R169: =J169*2% -> 0.059307872 | S169: =J169*2% -> 0.059307872 | T169: =J169*1% -> 0.029653936 | U169: =J169+Q169+R169+S169+T169 -> 3.2619329
A170: RCP-SMC-000167 | B170: SMC | C170: Croissant Zaatar and Baked Egg | D170: Wednesday | E170: Breakfast | F170: =SUMIF('Recipe Ingredients'!$A$5:$A$2237,'Master – Recipes'!A170,'Recipe Ingredients'!$O$5:$O$2237) -> 66790 | H170: =SUMIF('Recipe Ingredients'!$A$5:$A$2237,'Master – Recipes'!A170,'Recipe Ingredients'!$W$5:$W$2238) -> 2.2087505 | I170: =H170*10% -> 0.22087505 | J170: =H170+I170 -> 2.4296256 | Q170: =J170*5% -> 0.12148128 | R170: =J170*2% -> 0.048592511 | S170: =J170*2% -> 0.048592511 | T170: =J170*1% -> 0.024296256 | U170: =J170+Q170+R170+S170+T170 -> 2.6725881
A171: RCP-SMC-000168 | B171: SMC | C171: Pizza Veggie Margherita and Foul Medmas | D171: Thursday | E171: Breakfast | F171: =SUMIF('Recipe Ingredients'!$A$5:$A$2237,'Master – Recipes'!A171,'Recipe Ingredients'!$O$5:$O$2237) -> 6170 | H171: =SUMIF('Recipe Ingredients'!$A$5:$A$2237,'Master – Recipes'!A171,'Recipe Ingredients'!$W$5:$W$2238) -> 1.6183193 | I171: =H171*10% -> 0.16183193 | J171: =H171+I171 -> 1.7801512 | Q171: =J171*5% -> 0.089007559 | R171: =J171*2% -> 0.035603024 | S171: =J171*2% -> 0.035603024 | T171: =J171*1% -> 0.017801512 | U171: =J171+Q171+R171+S171+T171 -> 1.9581663
A172: RCP-SMC-000169 | B172: SMC | C172: Oats Porridge w/ Dried Mix Fruits and Boiled Egg | D172: Friday | E172: Breakfast | F172: =SUMIF('Recipe Ingredients'!$A$5:$A$2237,'Master – Recipes'!A172,'Recipe Ingredients'!$O$5:$O$2237) -> 3618 | H172: =SUMIF('Recipe Ingredients'!$A$5:$A$2237,'Master – Recipes'!A172,'Recipe Ingredients'!$W$5:$W$2238) -> 1.8521326 | I172: =H172*10% -> 0.18521326 | J172: =H172+I172 -> 2.0373459 | Q172: =J172*5% -> 0.10186729 | R172: =J172*2% -> 0.040746918 | S172: =J172*2% -> 0.040746918 | T172: =J172*1% -> 0.020373459 | U172: =J172+Q172+R172+S172+T172 -> 2.2410805
F173: =SUBTOTAL(109,F4:F172) -> 1390568.7 | H173: =SUBTOTAL(109,H4:H172) -> 502.03382 | I173: =SUBTOTAL(109,I4:I172) -> 50.203382 | J173: =SUBTOTAL(109,J4:J172) -> 552.23721 | K173: =SUBTOTAL(109,K4:K172) -> 0 | L173: =SUBTOTAL(109,L4:L172) -> 0 | M173: =SUBTOTAL(109,M4:M172) -> 0 | N173: =SUBTOTAL(109,N4:N172) -> 0 | O173: =SUBTOTAL(109,O4:O172) -> 1051.6609 | ... U173: =SUBTOTAL(109,U4:U172) -> 607.46093

Sheet Recipe Ingredients
A1: 📘 Master – SMC-Recipes Ingredients
A3: ▶ CONSOLIDATED INGREDIENT MASTER — SMC Recipes · Main + Sub Recipes
A4: Recipe Ref | B4: Brand Name | C4: Customer Name | D4: Recipe Name | E4: Days | F4: Section | G4: Category | H4: Order Type | I4: Sub Recipe Ref | J4: Ingredient Type | K4: Item Code | L4: Item / Ingredient | M4: UOM | N4: St. UOM | O4: Qty req per Batch (g/pcs) | P4: Gross Qty req Batch | Q4: Yield % | R4: No. of portions per batch | S4: Portion Size | T4: NET Qty req per portion | U4: GROSS Qty req per portion | V4: PP St. UOM | W4: Food Cost per portion
A5: RCP-SMC-00001 | B5: Gourmet360 | C5: SMC | D5: Thai shrimp curry with white rice | E5: Sunday | F5: Butchery Section | G5: Main Course | H5: Lunch | J5: Main Recipe | K5: =IFERROR(VLOOKUP(L5,'Raw material list'!$A$3:$C$715,3,0),"") -> SFD2-5320 | L5: Frz Shrimps (16/20) Without Tail | M5: Gram | N5: =VLOOKUP(L5,'Raw material list'!$A$3:$E$715,5,0) -> Gram | O5: 700 | P5: =O5/Q5*100 -> 1138.2114 | Q5: 61.5 | R5: 10 | T5: =IFERROR(O5/R5,0) -> 70 | U5: =IFERROR(P5/R5,0) -> 113.82114 | V5: =IFERROR(VLOOKUP(L5,'Raw material list'!$A$2:$S$3102,6,0),0) -> 0.115 | W5: =IFERROR(V5*U5,0) -> 13.089431
A6: RCP-SMC-00001 | B6: Gourmet360 | C6: SMC | D6: Thai shrimp curry with white rice | E6: Sunday | F6: Hot Section | G6: Main Course | H6: Lunch | K6: =IFERROR(VLOOKUP(L6,'Raw material list'!$A$3:$C$715,3,0),"") -> PRD1-4265 | L6: Fresh onion Yellow(Imported) | M6: Gram | N6: =VLOOKUP(L6,'Raw material list'!$A$3:$E$715,5,0) -> Gram | O6: 150 | P6: =O6/Q6*100 -> 176.47059 | Q6: 85 | R6: 10 | T6: =IFERROR(O6/R6,0) -> 15 | U6: =IFERROR(P6/R6,0) -> 17.647059 | V6: =IFERROR(VLOOKUP(L6,'Raw material list'!$A$2:$S$3102,6,0),0) -> 0.0035294118 | W6: =IFERROR(V6*U6,0) -> 0.062283737
A7: RCP-SMC-00001 | B7: Gourmet360 | C7: SMC | D7: Thai shrimp curry with white rice | E7: Sunday | F7: Hot Section | G7: Main Course | H7: Lunch | K7: =IFERROR(VLOOKUP(L7,'Raw material list'!$A$3:$C$715,3,0),"") -> DRS3-1813 | L7: Corn Oil (18 Liter) | M7: Ml | N7: =VLOOKUP(L7,'Raw material list'!$A$3:$E$715,5,0) -> Ml | O7: 30 | P7: =O7/Q7*100 -> 30 | Q7: 100 | R7: 10 | T7: =IFERROR(O7/R7,0) -> 3 | U7: =IFERROR(P7/R7,0) -> 3 | V7: =IFERROR(VLOOKUP(L7,'Raw material list'!$A$2:$S$3102,6,0),0) -> 0.0080555556 | W7: =IFERROR(V7*U7,0) -> 0.024166667
A8: RCP-SMC-00001 | B8: Gourmet360 | C8: SMC | D8: Thai shrimp curry with white rice | E8: Sunday | F8: Hot Section | G8: Main Course | H8: Lunch | K8: =IFERROR(VLOOKUP(L8,'Raw material list'!$A$3:$C$715,3,0),"") -> PRD1-4327 | L8: Fresh Garlic Peeled | M8: Gram | N8: =VLOOKUP(L8,'Raw material list'!$A$3:$E$715,5,0) -> Gram | O8: 10 | P8: =O8/Q8*100 -> 12.048193 | Q8: 83 | R8: 10 | T8: =IFERROR(O8/R8,0) -> 1 | U8: =IFERROR(P8/R8,0) -> 1.2048193 | V8: =IFERROR(VLOOKUP(L8,'Raw material list'!$A$2:$S$3102,6,0),0) -> 0.013 | W8: =IFERROR(V8*U8,0) -> 0.015662651
A9: RCP-SMC-00001 | B9: Gourmet360 | C9: SMC | D9: Thai shrimp curry with white rice | E9: Sunday | F9: Hot Section | G9: Main Course | H9: Lunch | K9: =IFERROR(VLOOKUP(L9,'Raw material list'!$A$3:$C$715,3,0),"") -> PRD1-204 | L9: Fresh Ginger | M9: Gram | N9: =VLOOKUP(L9,'Raw material list'!$A$3:$E$715,5,0) -> Gram | O9: 10 | P9: =O9/Q9*100 -> 12.048193 | Q9: 83 | R9: 10 | T9: =IFERROR(O9/R9,0) -> 1 | U9: =IFERROR(P9/R9,0) -> 1.2048193 | V9: =IFERROR(VLOOKUP(L9,'Raw material list'!$A$2:$S$3102,6,0),0) -> 0.0084337349 | W9: =IFERROR(V9*U9,0) -> 0.010161126
A10: RCP-SMC-00001 | B10: Gourmet360 | C10: SMC | D10: Thai shrimp curry with white rice | E10: Sunday | F10: Hot Section | G10: Main Course | H10: Lunch | K10: =IFERROR(VLOOKUP(L10,'Raw material list'!$A$3:$C$715,3,0),"") -> DRS1-472 | L10: Tom Yum Paste | M10: Gram | N10: =VLOOKUP(L10,'Raw material list'!$A$3:$E$715,5,0) -> Gram | O10: 40 | P10: =O10/Q10*100 -> 40 | Q10: 100 | R10: 10 | T10: =IFERROR(O10/R10,0) -> 4 | U10: =IFERROR(P10/R10,0) -> 4 | V10: =IFERROR(VLOOKUP(L10,'Raw material list'!$A$2:$S$3102,6,0),0) -> 0.088105727 | W10: =IFERROR(V10*U10,0) -> 0.35242291
A11: RCP-SMC-00001 | B11: Gourmet360 | C11: SMC | D11: Thai shrimp curry with white rice | E11: Sunday | F11: Hot Section | G11: Main Course | H11: Lunch | K11: =IFERROR(VLOOKUP(L11,'Raw material list'!$A$3:$C$715,3,0),"") -> DRS6-3608 | L11: Spice Curry Powder(Kg) | M11: Gram | N11: =VLOOKUP(L11,'Raw material list'!$A$3:$E$715,5,0) -> Gram | O11: 50 | P11: =O11/Q11*100 -> 50 | Q11: 100 | R11: 10 | T11: =IFERROR(O11/R11,0) -> 5 | U11: =IFERROR(P11/R11,0) -> 5 | V11: =IFERROR(VLOOKUP(L11,'Raw material list'!$A$2:$S$3102,6,0),0) -> 0.016 | W11: =IFERROR(V11*U11,0) -> 0.08
A12: RCP-SMC-00001 | B12: Gourmet360 | C12: SMC | D12: Thai shrimp curry with white rice | E12: Sunday | F12: Hot Section | G12: Main Course | H12: Lunch | K12: =IFERROR(VLOOKUP(L12,'Raw material list'!$A$3:$C$715,3,0),"") -> TAP-00001 | L12: Tap Water-Cooking | M12: Ml | N12: =VLOOKUP(L12,'Raw material list'!$A$3:$E$715,5,0) -> Ml | O12: 1200 | P12: =O12/Q12*100 -> 1200 | Q12: 100 | R12: 10 | T12: =IFERROR(O12/R12,0) -> 120 | U12: =IFERROR(P12/R12,0) -> 120 | V12: =IFERROR(VLOOKUP(L12,'Raw material list'!$A$2:$S$3102,6,0),0) -> 8e-05 | W12: =IFERROR(V12*U12,0) -> 0.0096
A13: RCP-SMC-00001 | B13: Gourmet360 | C13: SMC | D13: Thai shrimp curry with white rice | E13: Sunday | F13: Hot Section | G13: Main Course | H13: Lunch | K13: =IFERROR(VLOOKUP(L13,'Raw material list'!$A$3:$C$715,3,0),"") -> DRS1-3811 | L13: Chicken Stock Powder(Packet) | M13: Gram | N13: =VLOOKUP(L13,'Raw material list'!$A$3:$E$715,5,0) -> Gram | O13: 15 | P13: =O13/Q13*100 -> 15 | Q13: 100 | R13: 10 | T13: =IFERROR(O13/R13,0) -> 1.5 | U13: =IFERROR(P13/R13,0) -> 1.5 | V13: =IFERROR(VLOOKUP(L13,'Raw material list'!$A$2:$S$3102,6,0),0) -> 0.028475 | W13: =IFERROR(V13*U13,0) -> 0.0427125
A14: RCP-SMC-00001 | B14: Gourmet360 | C14: SMC | D14: Thai shrimp curry with white rice | E14: Sunday | F14: Hot Section | G14: Main Course | H14: Lunch | K14: =IFERROR(VLOOKUP(L14,'Raw material list'!$A$3:$C$715,3,0),"") -> PRD1-239 | L14: Fresh Sweet Pepper Green | M14: Gram | N14: =VLOOKUP(L14,'Raw material list'!$A$3:$E$715,5,0) -> Gram | O14: 80 | P14: =O14/Q14*100 -> 118.81188 | Q14: 67.333333 | R14: 10 | T14: =IFERROR(O14/R14,0) -> 8 | U14: =IFERROR(P14/R14,0) -> 11.881188 | V14: =IFERROR(VLOOKUP(L14,'Raw material list'!$A$2:$S$3102,6,0),0) -> 0.0066864785 | W14: =IFERROR(V14*U14,0) -> 0.079443308
A15: RCP-SMC-00001 | B15: Gourmet360 | C15: SMC | D15: Thai shrimp curry with white rice | E15: Sunday | F15: Hot Section | G15: Main Course | H15: Lunch | K15: =IFERROR(VLOOKUP(L15,'Raw material list'!$A$3:$C$715,3,0),"") -> PRD1-240 | L15: Fresh Sweet Pepper Red | M15: Gram | N15: =VLOOKUP(L15,'Raw material list'!$A$3:$E$715,5,0) -> Gram | O15: 80 | P15: =O15/Q15*100 -> 118.2266 | Q15: 67.666667 | R15: 10 | T15: =IFERROR(O15/R15,0) -> 8 | U15: =IFERROR(P15/R15,0) -> 11.82266 | V15: =IFERROR(VLOOKUP(L15,'Raw material list'!$A$2:$S$3102,6,0),0) -> 0.013293944 | W15: =IFERROR(V15*U15,0) -> 0.15716978
A16: RCP-SMC-00001 | B16: Gourmet360 | C16: SMC | D16: Thai shrimp curry with white rice | E16: Sunday | F16: Hot Section | G16: Main Course | H16: Lunch | K16: =IFERROR(VLOOKUP(L16,'Raw material list'!$A$3:$C$715,3,0),"") -> PRD1-241 | L16: Fresh Sweet Pepper Yellow | M16: Gram | N16: =VLOOKUP(L16,'Raw material list'!$A$3:$E$715,5,0) -> Gram | O16: 80 | P16: =O16/Q16*100 -> 117.24475 | Q16: 68.233333 | R16: 10 | T16: =IFERROR(O16/R16,0) -> 8 | U16: =IFERROR(P16/R16,0) -> 11.724475 | V16: =IFERROR(VLOOKUP(L16,'Raw material list'!$A$2:$S$3102,6,0),0) -> 0.013196481 | W16: =IFERROR(V16*U16,0) -> 0.15472181
A17: RCP-SMC-00001 | B17: Gourmet360 | C17: SMC | D17: Thai shrimp curry with white rice | E17: Sunday | F17: Hot Section | G17: Main Course | H17: Lunch | K17: =IFERROR(VLOOKUP(L17,'Raw material list'!$A$3:$C$715,3,0),"") -> DRS5-21 | L17: Flour Corn | M17: Gram | N17: =VLOOKUP(L17,'Raw material list'!$A$3:$E$715,5,0) -> Gram | O17: 60 | P17: =O17/Q17*100 -> 60 | Q17: 100 | R17: 10 | T17: =IFERROR(O17/R17,0) -> 6 | U17: =IFERROR(P17/R17,0) -> 6 | V17: =IFERROR(VLOOKUP(L17,'Raw material list'!$A$2:$S$3102,6,0),0) -> 0.00208 | W17: =IFERROR(V17*U17,0) -> 0.01248
... A662: RCP-SMC-000037 | B662: Gourmet360 | C662: SMC | D662: Beef kaldereta with soft rice | E662: Thursday | F662: Butchery Section | G662: Main Course | H662: Lunch | K662: =IFERROR(VLOOKUP(L662,'Raw material list'!$A$3:$C$715,3,0),"") -> MET2-1051 | L662: Frz Beef Tendrloin Brazil | M662: Gram | N662: =VLOOKUP(L662,'Raw material list'!$A$3:$E$715,5,0) -> Gram | O662: 1000 | P662: =O662/Q662*100 -> 1945.5253 | Q662: 51.4 | R662: 10 | T662: =IFERROR(O662/R662,0) -> 100 | U662: =IFERROR(P662/R662,0) -> 194.55253 | V662: =IFERROR(VLOOKUP(L662,'Raw material list'!$A$2:$S$3102,6,0),0) -> 0.084705882 | W662: =IFERROR(V662*U662,0) -> 16.479744
A663: RCP-SMC-000037 | B663: Gourmet360 | C663: SMC | D663: =D662 -> Beef kaldereta with soft rice | E663: Thursday | F663: Hot Section | G663: Main Course | H663: Lunch | K663: =IFERROR(VLOOKUP(L663,'Raw material list'!$A$3:$C$715,3,0),"") -> DRS3-1813 | L663: Corn Oil (18 Liter) | M663: Ml | N663: =VLOOKUP(L663,'Raw material list'!$A$3:$E$715,5,0) -> Ml | O663: 40 | P663: =O663/Q663*100 -> 40 | Q663: 100 | R663: 10 | T663: =IFERROR(O663/R663,0) -> 4 | U663: =IFERROR(P663/R663,0) -> 4 | V663: =IFERROR(VLOOKUP(L663,'Raw material list'!$A$2:$S$3102,6,0),0) -> 0.0080555556 | W663: =IFERROR(V663*U663,0) -> 0.032222222
A664: RCP-SMC-000037 | B664: Gourmet360 | C664: SMC | D664: =D663 -> Beef kaldereta with soft rice | E664: Thursday | F664: Hot Section | G664: Main Course | H664: Lunch | K664: =IFERROR(VLOOKUP(L664,'Raw material list'!$A$3:$C$715,3,0),"") -> PRD1-4327 | L664: Fresh Garlic Peeled | M664: Gram | N664: =VLOOKUP(L664,'Raw material list'!$A$3:$E$715,5,0) -> Gram | O664: 20 | P664: =O664/Q664*100 -> 24.096386 | Q664: 83 | R664: 10 | T664: =IFERROR(O664/R664,0) -> 2 | U664: =IFERROR(P664/R664,0) -> 2.4096386 | V664: =IFERROR(VLOOKUP(L664,'Raw material list'!$A$2:$S$3102,6,0),0) -> 0.013 | W664: =IFERROR(V664*U664,0) -> 0.031325301
A665: RCP-SMC-000037 | B665: Gourmet360 | C665: SMC | D665: =D664 -> Beef kaldereta with soft rice | E665: Thursday | F665: Hot Section | G665: Main Course | H665: Lunch | K665: =IFERROR(VLOOKUP(L665,'Raw material list'!$A$3:$C$715,3,0),"") -> PRD1-204 | L665: Fresh Ginger | M665: Gram | N665: =VLOOKUP(L665,'Raw material list'!$A$3:$E$715,5,0) -> Gram | O665: 25 | P665: =O665/Q665*100 -> 30.120482 | Q665: 83 | R665: 10 | T665: =IFERROR(O665/R665,0) -> 2.5 | U665: =IFERROR(P665/R665,0) -> 3.0120482 | V665: =IFERROR(VLOOKUP(L665,'Raw material list'!$A$2:$S$3102,6,0),0) -> 0.0084337349 | W665: =IFERROR(V665*U665,0) -> 0.025402816
A666: RCP-SMC-000037 | B666: Gourmet360 | C666: SMC | D666: =D665 -> Beef kaldereta with soft rice | E666: Thursday | F666: Hot Section | G666: Main Course | H666: Lunch | K666: =IFERROR(VLOOKUP(L666,'Raw material list'!$A$3:$C$715,3,0),"") -> DRS1-3912 | L666: Soya Sauce,Sempio (930 Mliter) | M666: Ml | N666: =VLOOKUP(L666,'Raw material list'!$A$3:$E$715,5,0) -> Ml | O666: 50 | P666: =O666/Q666*100 -> 50 | Q666: 100 | R666: 10 | T666: =IFERROR(O666/R666,0) -> 5 | U666: =IFERROR(P666/R666,0) -> 5 | V666: =IFERROR(VLOOKUP(L666,'Raw material list'!$A$2:$S$3102,6,0),0) -> 0.014731707 | W666: =IFERROR(V666*U666,0) -> 0.073658537
A667: RCP-SMC-000037 | B667: Gourmet360 | C667: SMC | D667: =D666 -> Beef kaldereta with soft rice | E667: Thursday | F667: Hot Section | G667: Main Course | H667: Lunch | K667: =IFERROR(VLOOKUP(L667,'Raw material list'!$A$3:$C$715,3,0),"") -> DRS6-3593 | L667: Spices Bay Leaves | M667: Gram | N667: =VLOOKUP(L667,'Raw material list'!$A$3:$E$715,5,0) -> Gram | O667: 1 | P667: =O667/Q667*100 -> 1 | Q667: 100 | R667: 10 | T667: =IFERROR(O667/R667,0) -> 0.1 | U667: =IFERROR(P667/R667,0) -> 0.1 | V667: =IFERROR(VLOOKUP(L667,'Raw material list'!$A$2:$S$3102,6,0),0) -> 0.008 | W667: =IFERROR(V667*U667,0) -> 0.0008
A668: RCP-SMC-000037 | B668: Gourmet360 | C668: SMC | D668: =D667 -> Beef kaldereta with soft rice | E668: Thursday | F668: Hot Section | G668: Main Course | H668: Lunch | K668: =IFERROR(VLOOKUP(L668,'Raw material list'!$A$3:$C$715,3,0),"") -> DRS1-978 | L668: Sugar Fine(50 KG) | M668: Gram | N668: =VLOOKUP(L668,'Raw material list'!$A$3:$E$715,5,0) -> Gram | O668: 30 | P668: =O668/Q668*100 -> 30 | Q668: 100 | R668: 10 | T668: =IFERROR(O668/R668,0) -> 3 | U668: =IFERROR(P668/R668,0) -> 3 | V668: =IFERROR(VLOOKUP(L668,'Raw material list'!$A$2:$S$3102,6,0),0) -> 0.0024 | W668: =IFERROR(V668*U668,0) -> 0.0072
A669: RCP-SMC-000037 | B669: Gourmet360 | C669: SMC | D669: =D668 -> Beef kaldereta with soft rice | E669: Thursday | F669: Hot Section | G669: Main Course | H669: Lunch | K669: =IFERROR(VLOOKUP(L669,'Raw material list'!$A$3:$C$715,3,0),"") -> DRS1-1747 | L669: Can Tomato Paste (4500 Gram) | M669: Gram | N669: =VLOOKUP(L669,'Raw material list'!$A$3:$E$715,5,0) -> Gram | O669: 100 | P669: =O669/Q669*100 -> 100 | Q669: 100 | R669: 10 | T669: =IFERROR(O669/R669,0) -> 10 | U669: =IFERROR(P669/R669,0) -> 10 | V669: =IFERROR(VLOOKUP(L669,'Raw material list'!$A$2:$S$3102,6,0),0) -> 0.0051851852 | W669: =IFERROR(V669*U669,0) -> 0.051851852
A670: RCP-SMC-000037 | B670: Gourmet360 | C670: SMC | D670: =D669 -> Beef kaldereta with soft rice | E670: Thursday | F670: Hot Section | G670: Main Course | H670: Lunch | K670: =IFERROR(VLOOKUP(L670,'Raw material list'!$A$3:$C$715,3,0),"") -> TAP-00001 | L670: Tap Water-Cooking | M670: Ml | N670: =VLOOKUP(L670,'Raw material list'!$A$3:$E$715,5,0) -> Ml | O670: 1800 | P670: =O670/Q670*100 -> 1800 | Q670: 100 | R670: 10 | T670: =IFERROR(O670/R670,0) -> 180 | U670: =IFERROR(P670/R670,0) -> 180 | V670: =IFERROR(VLOOKUP(L670,'Raw material list'!$A$2:$S$3102,6,0),0) -> 8e-05 | W670: =IFERROR(V670*U670,0) -> 0.0144
A671: RCP-SMC-000037 | B671: Gourmet360 | C671: SMC | D671: =D670 -> Beef kaldereta with soft rice | E671: Thursday | F671: Hot Section | G671: Main Course | H671: Lunch | K671: =IFERROR(VLOOKUP(L671,'Raw material list'!$A$3:$C$715,3,0),"") -> PRD1-240 | L671: Fresh Sweet Pepper Red | M671: Gram | N671: =VLOOKUP(L671,'Raw material list'!$A$3:$E$715,5,0) -> Gram | O671: 100 | P671: =O671/Q671*100 -> 147.78325 | Q671: 67.666667 | R671: 10 | T671: =IFERROR(O671/R671,0) -> 10 | U671: =IFERROR(P671/R671,0) -> 14.778325 | V671: =IFERROR(VLOOKUP(L671,'Raw material list'!$A$2:$S$3102,6,0),0) -> 0.013293944 | W671: =IFERROR(V671*U671,0) -> 0.19646222
A672: RCP-SMC-000037 | B672: Gourmet360 | C672: SMC | D672: =D671 -> Beef kaldereta with soft rice | E672: Thursday | F672: Hot Section | G672: Main Course | H672: Lunch | K672: =IFERROR(VLOOKUP(L672,'Raw material list'!$A$3:$C$715,3,0),"") -> PRD1-186 | L672: Fresh Carrot Imported | M672: Gram | N672: =VLOOKUP(L672,'Raw material list'!$A$3:$E$715,5,0) -> Gram | O672: 300 | P672: =O672/Q672*100 -> 367.34694 | Q672: 81.666667 | R672: 10 | T672: =IFERROR(O672/R672,0) -> 30 | U672: =IFERROR(P672/R672,0) -> 36.734694 | V672: =IFERROR(VLOOKUP(L672,'Raw material list'!$A$2:$S$3102,6,0),0) -> 0.0058139535 | W672: =IFERROR(V672*U672,0) -> 0.2135738
A673: RCP-SMC-000037 | B673: Gourmet360 | C673: SMC | D673: =D672 -> Beef kaldereta with soft rice | E673: Thursday | F673: Hot Section | G673: Main Course | H673: Lunch | K673: =IFERROR(VLOOKUP(L673,'Raw material list'!$A$3:$C$715,3,0),"") -> PRD1-230 | L673: Fresh Potato | M673: Gram | N673: =VLOOKUP(L673,'Raw material list'!$A$3:$E$715,5,0) -> Gram | O673: 400 | P673: =O673/Q673*100 -> 539.81107 | Q673: 74.1 | R673: 10 | T673: =IFERROR(O673/R673,0) -> 40 | U673: =IFERROR(P673/R673,0) -> 53.981107 | V673: =IFERROR(VLOOKUP(L673,'Raw material list'!$A$2:$S$3102,6,0),0) -> 0.0033738192 | W673: =IFERROR(V673*U673,0) -> 0.18212249
A674: RCP-SMC-000037 | B674: Gourmet360 | C674: SMC | D674: =D673 -> Beef kaldereta with soft rice | E674: Thursday | F674: Hot Section | G674: Main Course | H674: Lunch | K674: =IFERROR(VLOOKUP(L674,'Raw material list'!$A$3:$C$715,3,0),"") -> DRS1-110 | L674: Sauce Oyster | M674: Ml | N674: =VLOOKUP(L674,'Raw material list'!$A$3:$E$715,5,0) -> Ml | O674: 200 | P674: =O674/Q674*100 -> 200 | Q674: 100 | R674: 10 | T674: =IFERROR(O674/R674,0) -> 20 | U674: =IFERROR(P674/R674,0) -> 20 | V674: =IFERROR(VLOOKUP(L674,'Raw material list'!$A$2:$S$3102,6,0),0) -> 0.01805 | W674: =IFERROR(V674*U674,0) -> 0.361
... A679: RCP-SMC-000037 | B679: Gourmet360 | C679: SMC | D679: =D678 -> Beef kaldereta with soft rice | E679: Thursday | F679: Hot Section | G679: Main Course | H679: Lunch | K679: =IFERROR(VLOOKUP(L679,'Raw material list'!$A$3:$C$715,3,0),"") -> PRD1-241 | L679: Fresh Sweet Pepper Yellow | M679: Gram | N679: =VLOOKUP(L679,'Raw material list'!$A$3:$E$715,5,0) -> Gram | O679: 100 | P679: =O679/Q679*100 -> 146.55594 | Q679: 68.233333 | R679: 10 | T679: =IFERROR(O679/R679,0) -> 10 | U679: =IFERROR(P679/R679,0) -> 14.655594 | V679: =IFERROR(VLOOKUP(L679,'Raw material list'!$A$2:$S$3102,6,0),0) -> 0.013196481 | W679: =IFERROR(V679*U679,0) -> 0.19340226
A680: RCP-SMC-000038 | B680: Gourmet360 | C680: SMC | D680: Meat Mandi with tahina sauce | E680: Thursday | F680: Hot Section | G680: Main Course | H680: Lunch | K680: =IFERROR(VLOOKUP(L680,'Raw material list'!$A$3:$C$715,3,0),"") -> DRS3-1813 | L680: Corn Oil (18 Liter) | M680: Ml | N680: =VLOOKUP(L680,'Raw material list'!$A$3:$E$715,5,0) -> Ml | O680: 40 | P680: =O680/Q680*100 -> 40 | Q680: 100 | R680: 10 | T680: =IFERROR(O680/R680,0) -> 4 | U680: =IFERROR(P680/R680,0) -> 4 | V680: =IFERROR(VLOOKUP(L680,'Raw material list'!$A$2:$S$3102,6,0),0) -> 0.0080555556 | W680: =IFERROR(V680*U680,0) -> 0.032222222
A681: RCP-SMC-000038 | B681: Gourmet360 | C681: SMC | D681: =D680 -> Meat Mandi with tahina sauce | E681: Thursday | F681: Hot Section | G681: Main Course | H681: Lunch | K681: =IFERROR(VLOOKUP(L681,'Raw material list'!$A$3:$C$715,3,0),"") -> PRD1-4265 | L681: Fresh onion Yellow(Imported) | M681: Gram | N681: =VLOOKUP(L681,'Raw material list'!$A$3:$E$715,5,0) -> Gram | O681: 150 | P681: =O681/Q681*100 -> 176.47059 | Q681: 85 | R681: 10 | T681: =IFERROR(O681/R681,0) -> 15 | U681: =IFERROR(P681/R681,0) -> 17.647059 | V681: =IFERROR(VLOOKUP(L681,'Raw material list'!$A$2:$S$3102,6,0),0) -> 0.0035294118 | W681: =IFERROR(V681*U681,0) -> 0.062283737
A682: RCP-SMC-000038 | B682: Gourmet360 | C682: SMC | D682: =D681 -> Meat Mandi with tahina sauce | E682: Thursday | F682: Hot Section | G682: Main Course | H682: Lunch | K682: =IFERROR(VLOOKUP(L682,'Raw material list'!$A$3:$C$715,3,0),"") -> PRD1-4327 | L682: Fresh Garlic Peeled | M682: Gram | N682: =VLOOKUP(L682,'Raw material list'!$A$3:$E$715,5,0) -> Gram | O682: 10 | P682: =O682/Q682*100 -> 12.048193 | Q682: 83 | R682: 10 | T682: =IFERROR(O682/R682,0) -> 1 | U682: =IFERROR(P682/R682,0) -> 1.2048193 | V682: =IFERROR(VLOOKUP(L682,'Raw material list'!$A$2:$S$3102,6,0),0) -> 0.013 | W682: =IFERROR(V682*U682,0) -> 0.015662651
A683: RCP-SMC-000038 | B683: Gourmet360 | C683: SMC | D683: =D682 -> Meat Mandi with tahina sauce | E683: Thursday | F683: Hot Section | G683: Main Course | H683: Lunch | K683: =IFERROR(VLOOKUP(L683,'Raw material list'!$A$3:$C$715,3,0),"") -> DRS1-304 | L683: Food Color Yellow(Saffron) | M683: Gram | N683: =VLOOKUP(L683,'Raw material list'!$A$3:$E$715,5,0) -> Gram | O683: 1 | P683: =O683/Q683*100 -> 1 | Q683: 100 | R683: 10 | T683: =IFERROR(O683/R683,0) -> 0.1 | U683: =IFERROR(P683/R683,0) -> 0.1 | V683: =IFERROR(VLOOKUP(L683,'Raw material list'!$A$2:$S$3102,6,0),0) -> 0.0208 | W683: =IFERROR(V683*U683,0) -> 0.00208
A684: RCP-SMC-000038 | B684: Gourmet360 | C684: SMC | D684: =D683 -> Meat Mandi with tahina sauce | E684: Thursday | F684: Hot Section | G684: Main Course | H684: Lunch | K684: =IFERROR(VLOOKUP(L684,'Raw material list'!$A$3:$C$715,3,0),"") -> TAP-00001 | L684: Tap Water-Cooking | M684: Ml | N684: =VLOOKUP(L684,'Raw material list'!$A$3:$E$715,5,0) -> Ml | O684: 1800 | P684: =O684/Q684*100 -> 1800 | Q684: 100 | R684: 10 | T684: =IFERROR(O684/R684,0) -> 180 | U684: =IFERROR(P684/R684,0) -> 180 | V684: =IFERROR(VLOOKUP(L684,'Raw material list'!$A$2:$S$3102,6,0),0) -> 8e-05 | W684: =IFERROR(V684*U684,0) -> 0.0144
A685: RCP-SMC-000038 | B685: Gourmet360 | C685: SMC | D685: =D684 -> Meat Mandi with tahina sauce | E685: Thursday | F685: Hot Section | G685: Main Course | H685: Lunch | K685: =IFERROR(VLOOKUP(L685,'Raw material list'!$A$3:$C$715,3,0),"") -> DRS4-498 | L685: Rice Basmati | M685: Gram | N685: =VLOOKUP(L685,'Raw material list'!$A$3:$E$715,5,0) -> Gram | O685: 1000 | P685: =O685/Q685*100 -> 1000 | Q685: 100 | R685: 10 | T685: =IFERROR(O685/R685,0) -> 100 | U685: =IFERROR(P685/R685,0) -> 100 | V685: =IFERROR(VLOOKUP(L685,'Raw material list'!$A$2:$S$3102,6,0),0) -> 0.00575 | W685: =IFERROR(V685*U685,0) -> 0.575
A686: RCP-SMC-000038 | B686: Gourmet360 | C686: SMC | D686: =D685 -> Meat Mandi with tahina sauce | E686: Thursday | F686: Hot Section | G686: Main Course | H686: Lunch | K686: =IFERROR(VLOOKUP(L686,'Raw material list'!$A$3:$C$715,3,0),"") -> DRS1-3811 | L686: Chicken Stock Powder(Packet) | M686: Gram | N686: =VLOOKUP(L686,'Raw material list'!$A$3:$E$715,5,0) -> Gram | O686: 20 | P686: =O686/Q686*100 -> 20 | Q686: 100 | R686: 10 | T686: =IFERROR(O686/R686,0) -> 2 | U686: =IFERROR(P686/R686,0) -> 2 | V686: =IFERROR(VLOOKUP(L686,'Raw material list'!$A$2:$S$3102,6,0),0) -> 0.028475 | W686: =IFERROR(V686*U686,0) -> 0.05695
A687: RCP-SMC-000038 | B687: Gourmet360 | C687: SMC | D687: =D686 -> Meat Mandi with tahina sauce | E687: Thursday | F687: Hot Section | G687: Main Course | H687: Lunch | K687: =IFERROR(VLOOKUP(L687,'Raw material list'!$A$3:$C$715,3,0),"") -> DRY2-1008 | L687: Butter 82% Fat(Unsalted) 25 kg | M687: Gram | N687: =VLOOKUP(L687,'Raw material list'!$A$3:$E$715,5,0) -> Gram | O687: 20 | P687: =O687/Q687*100 -> 20 | Q687: 100 | R687: 10 | T687: =IFERROR(O687/R687,0) -> 2 | U687: =IFERROR(P687/R687,0) -> 2 | V687: =IFERROR(VLOOKUP(L687,'Raw material list'!$A$2:$S$3102,6,0),0) -> 0.03 | W687: =IFERROR(V687*U687,0) -> 0.06
A688: RCP-SMC-000038 | B688: Gourmet360 | C688: SMC | D688: =D687 -> Meat Mandi with tahina sauce | E688: Thursday | F688: Hot Section | G688: Main Course | H688: Lunch | K688: =IFERROR(VLOOKUP(L688,'Raw material list'!$A$3:$C$715,3,0),"") -> DRS6-1020 | L688: Spices Cloves Seeds | M688: Gram | N688: =VLOOKUP(L688,'Raw material list'!$A$3:$E$715,5,0) -> Gram | O688: 1 | P688: =O688/Q688*100 -> 1 | Q688: 100 | R688: 10 | T688: =IFERROR(O688/R688,0) -> 0.1 | U688: =IFERROR(P688/R688,0) -> 0.1 | V688: =IFERROR(VLOOKUP(L688,'Raw material list'!$A$2:$S$3102,6,0),0) -> 0.055 | W688: =IFERROR(V688*U688,0) -> 0.0055
A689: RCP-SMC-000038 | B689: Gourmet360 | C689: SMC | D689: =D688 -> Meat Mandi with tahina sauce | E689: Thursday | F689: Hot Section | G689: Main Course | H689: Lunch | K689: =IFERROR(VLOOKUP(L689,'Raw material list'!$A$3:$C$715,3,0),"") -> PRD3-1675 | L689: Dry Lemon Black(1 Kg) | M689: Gram | N689: =VLOOKUP(L689,'Raw material list'!$A$3:$E$715,5,0) -> Gram | O689: 2 | P689: =O689/Q689*100 -> 2 | Q689: 100 | R689: 10 | T689: =IFERROR(O689/R689,0) -> 0.2 | U689: =IFERROR(P689/R689,0) -> 0.2 | V689: =IFERROR(VLOOKUP(L689,'Raw material list'!$A$2:$S$3102,6,0),0) -> 0.012 | W689: =IFERROR(V689*U689,0) -> 0.0024
...

Sheet Raw material list
C1: Master Raw Material
A2: Items Description | C2: Code | D2: NameEN | E2: Unit | F2: Price | G2: Main category | H2: Sub category
A3: Bran Bread Brown (Diet) | C3: BKR1-1917 | D3: Bran Bread Brown (Diet) | E3: Each | F3: 0.95 | G3: Fresh | H3: Bakery
A4: Bread Arabic Brown (6 each) 400211 | C4: BKR1-3695 | D4: Bread Arabic Brown (6 each) 400211 | E4: Each | F4: 0.16666667 | G4: Fresh | H4: Bakery
A5: Bread Arabic White(7 Each) 400210 | C5: BKR1-3694 | D5: Bread Arabic White(7 Each) 400210 | E5: Each | F5: 0.14285714 | G5: Fresh | H5: Bakery
A6: Bread Burger Bun Brown(Each) | C6: BKR1-3791 | D6: Bread Burger Bun Brown(Each) | E6: Each | F6: 1 | G6: Fresh | H6: Bakery
A7: Bread Crumb IMP(Packet) | C7: BKR1-4011 | D7: Bread Crumb IMP(Packet) | E7: Gram | F7: 0.022 | G7: Fresh | H7: Bakery
A8: Bread Jumbo Sandwich White 400007 | C8: BKR1-1328 | D8: Bread Jumbo Sandwich White 400007 | E8: Each | F8: 1 | G8: Fresh | H8: Bakery
A9: Bread Potato Burger Plain | C9: BKR1-4332 | D9: Bread Potato Burger Plain | E9: Each | F9: 0.55833333 | G9: Fresh | H9: Bakery
A10: Bread Shawarma | C10: BKR1-1575 | D10: Bread Shawarma | E10: Each | F10: 0.12 | G10: Fresh | H10: Bakery
A11: Bread Sliced Brown Med-400001 | C11: BKR1-1327 | D11: Bread Sliced Brown Med-400001 | E11: Slice | F11: 0.22222222 | G11: Fresh | H11: Bakery
A12: Sticker roll expiry | C12: PKG-5310 | D12: Sticker roll expiry | E12: Each | F12: =6/1000 -> 0.006
A13: Bread Sliced White Med-400000 | C13: BKR1-1326 | D13: Bread Sliced White Med-400000 | E13: Slice | F13: 0.16666667 | G13: Fresh | H13: Bakery
A14: Fresh Bread Baguette Long Brown | C14: BKR1-3428 | D14: Fresh Bread Baguette Long Brown | E14: Each | F14: 4.78 | G14: Fresh | H14: Bakery
A15: Frz Kunafa Dough | C15: BKR1-1910 | D15: Frz Kunafa Dough | E15: Gram | F15: 0.01366 | G15: Fozen | H15: Bakery
A16: Milk Bread Mini 9Pcs | C16: BKR1-2125 | D16: Milk Bread Mini 9Pcs | E16: Each | F16: 0.44444444 | G16: Fresh | H16: Bakery
A17: Qursan | C17: BKR1-4717 | D17: Qursan | E17: Gram | F17: 0.013 | G17: Fresh | H17: Bakery
A18: Tart Shell Round Mini 3.7 Cm,Sweet | C18: BKR1-4132 | D18: Tart Shell Round Mini 3.7 Cm,Sweet | E18: Each | F18: 0.84126984 | G18: Fresh | H18: Bakery
A19: Bread Tortilla White,20cm(Fonte) | C19: BKR2-4274 | D19: Bread Tortilla White,20cm(Fonte) | E19: Each | F19: 0.625 | G19: Frozen | H19: Bakery
A20: Bread Tortilla White,30cm(Fonte) | C20: BKR2-4275 | D20: Bread Tortilla White,30cm(Fonte) | E20: Each | F20: 0.83333333 | G20: Frozen | H20: Bakery
A21: Frz Bread Baguette French (40080009) | C21: BKR2-2058 | D21: Frz Bread Baguette French (40080009) | E21: Gram | F21: 0.0066666667 | G21: Frozen | H21: Bakery
A22: Frz Bread Baguette Multicereal (40080109) | C22: BKR2-2059 | D22: Frz Bread Baguette Multicereal (40080109) | E22: Gram | F22: 0.01 | G22: Frozen | H22: Bakery
A23: Frz Bread Jumbo Sandwich 400017 | C23: BKR2-5081 | D23: Frz Bread Jumbo Sandwich 400017 | E23: Each | F23: 0.96666667 | G23: Frozen | H23: Bakery
A24: Frz Bread Panini (90 Gram) | C24: BKR2-4596 | D24: Frz Bread Panini (90 Gram) | E24: Each | F24: 0.96 | G24: Frozen | H24: Bakery
... A248: Syrup Chocolate (Hershey's) 680 Gram | C248: DRS1-616 | D248: Syrup Chocolate (Hershey's) 680 Gram | E248: Gram | F248: 0.024264706 | G248: Dry | H248: Pastry & Bakery
A249: Tea Biscuits(160 Gram) | C249: DRS1-3600 | D249: Tea Biscuits(160 Gram) | E249: Gram | F249: #DIV/0! | G249: Dry | H249: Pastry & Bakery
A250: Toffee Caramel,Gold(5 Kg) | C250: DRS1-3634 | D250: Toffee Caramel,Gold(5 Kg) | E250: Gram | F250: 0.0186 | G250: Dry | H250: Pastry & Bakery
A251: Vanilla Essence (Concentrated) | C251: DRS1-1823 | D251: Vanilla Essence (Concentrated) | E251: Gram | F251: 0.049 | G251: Dry | H251: Pastry & Bakery
A252: White Chocolate Coins 29% (Icam) | C252: DRS1-4358 | D252: White Chocolate Coins 29% (Icam) | E252: Gram | F252: 0.042 | G252: Dry | H252: Pastry & Bakery
A253: Xanthan Gum | C253: DRS1-5140 | D253: Xanthan Gum | E253: Gram | F253: 0.3 | G253: Dry | H253: Pastry & Bakery
A254: Bread Improver K2 | C254: DRS5-1325 | D254: Bread Improver K2 | E254: Gram | F254: 0.0117 | G254: Dry | H254: Pastry & Bakery
A255: Brownies Mix Powder(10 kg) | C255: DRS5-5001 | D255: Brownies Mix Powder(10 kg) | E255: Gram | F255: 0.0119 | G255: Dry | H255: Pastry & Bakery
A256: Cake Mix Powder,Red Velvet (10 kg) | C256: DRS5-5476 | D256: Cake Mix Powder,Red Velvet (10 kg) | E256: Gram | F256: 0.0085 | G256: Dry | H256: Pastry & Bakery
A257: Cocoa Powder (25 KG) | C257: DRS5-1736 | D257: Cocoa Powder (25 KG) | E257: Gram | F257: 0.038 | G257: Dry | H257: Pastry & Bakery
A258: Cream Caramel Mix Powder 5 kg | C258: DRS5-5427 | D258: Cream Caramel Mix Powder 5 kg | E258: Gram | F258: 0.019 | G258: Dry | H258: Pastry & Bakery
A259: Cream patissiere Custard Powder | C259: DRS5-4244 | D259: Cream patissiere Custard Powder | E259: Gram | F259: 0.023 | G259: Dry | H259: Pastry & Bakery
A260: Custard powder(450 Gram) | C260: DRS5-618 | D260: Custard powder(450 Gram) | E260: Gram | F260: 0.015288889 | G260: Dry | H260: Pastry & Bakery
A261: Easy Muffin Mix Chocolate (10 KG) | C261: DRS5-1624 | D261: Easy Muffin Mix Chocolate (10 KG) | E261: Gram | F261: 0.01 | G261: Dry | H261: Pastry & Bakery
... A388: water 200 ML (Nova) | C388: BVG3-4131 | D388: water 200 ML (Nova) | E388: Each | F388: 0.38 | G388: Beverage | H388: Water
A389: water 330 ML (Nova) | D389: water 330 ML (Nova) | E389: Each | F389: 0.3875 | G389: Beverage | H389: Water
...

Sheet Per Patient Serving
C2: SMC Regular per Patient Serving
C4: BreakFast | D4: Items | E4: Qty | F4: Sunday | G4: Monday | H4: Tuesday | I4: Wednesday | J4: Thursday | K4: Friday | L4: Saturday
D5: Breakfast main order | E5: 2 | F5: =('Sunday '!G12-F6)*2 -> 2.3108955 | G5: =(Monday!G12-G6)*2 -> 1.5732824 | H5: =(Tuesday!G12-H6)*2 -> 2.191472 | I5: =(Wednesday!G12-I6)*2 -> 2.0818671 | J5: =(Thursday!G12-J6)*2 -> 1.8971435 | K5: =('Friday '!G11-K6)*2 -> 1.7604291 | L5: =('Saturday '!G12-L6)*2 -> 1.621076
D6: Side Vegitable | E6: 1 | F6: ='Sunday '!F11 -> 0.80984619 | G6: =Monday!F11 -> 0.80984619 | H6: =Tuesday!F11 -> 0.80984619 | I6: =Wednesday!F11 -> 0.80984619 | J6: =Thursday!F11 -> 0.80984619 | K6: ='Friday '!F10 -> 0.80984619 | L6: ='Saturday '!F11 -> 0.80984619
D7: Set Sugar,Tea.or Coffee | E7: 1 | F7: ='Raw material list'!F339 -> 0.035 | G7: 0.035 | H7: 0.035 | I7: 0.035 | J7: 0.035 | K7: 0.035 | L7: 0.035
D8: Set Bread White or Brown for Diet Patient | E8: 1 | F8: ='Raw material list'!F13 -> 0.16666667 | G8: 0.16666667 | H8: 0.16666667 | I8: 0.16666667 | J8: 0.16666667 | K8: 0.16666667 | L8: 0.16666667
D9: Cup with lid | E9: 1 | M9: Packing
D10: Milk Cold | E10: 1 | F10: ='Raw material list'!F151 -> 0.00425 | G10: 0.00425 | H10: 0.00425 | I10: 0.00425 | J10: 0.00425 | K10: 0.00425 | L10: 0.00425
D11: Cutlaries set | E11: 1 | M11: Packing
D12: Cheese+ Honey or Jam portion | E12: 1 | F12: ='Raw material list'!F74 -> 0.38 | G12: 0.38 | H12: 0.38 | I12: 0.38 | J12: 0.38 | K12: 0.38 | L12: 0.38
D13: Water bottle 330 ML | E13: 2 | F13: ='Raw material list'!F389*2 -> 0.775 | G13: =0.3875*2 -> 0.775 | H13: =0.3875*2 -> 0.775 | I13: =0.3875*2 -> 0.775 | J13: =0.3875*2 -> 0.775 | K13: =0.3875*2 -> 0.775 | L13: =0.3875*2 -> 0.775
C14: Lunch | D14: Soup | E14: 1 | F14: ='Sunday '!G18 -> 1.1699071 | G14: =Monday!G17 -> 0.62573863 | H14: =Tuesday!G18 -> 0.78345693 | I14: =Wednesday!G18 -> 0.93608825 | J14: =Thursday!G17 -> 0.62573863 | K14: ='Friday '!G17 -> 0.76189772 | L14: ='Saturday '!G18 -> 0.84770267
D15: Salad | E15: 1 | F15: ='Sunday '!G21 -> 1.8050341 | G15: =Monday!G20 -> 1.6720592 | H15: =Tuesday!G21 -> 1.2953686 | I15: =Wednesday!G21 -> 1.8050341 | J15: =Thursday!G20 -> 2.1174144 | K15: ='Friday '!G20 -> 2.0389808 | L15: ='Saturday '!G21 -> 1.7068405
D16: Main course (Ckicken,Beef, Fish) or Pasta | E16: 1 | F16: =MAX('Sunday '!G25:G35) -> 8.5369958 | G16: =MAX(Monday!G24:G35) -> 7.8680767 | H16: =MAX(Tuesday!G25:G35) -> 5.3947808 | I16: =MAX(Wednesday!G24:G35) -> 5.7874866 | J16: =MAX(Thursday!G23:G34) -> 8.5863302 | K16: =MAX('Friday '!G24:G33) -> 5.9494364 | L16: =MAX('Saturday '!G25:G35) -> 6.0152959
D17: Fruit | E17: 1 | F17: ='Master – Recipes'!J79 -> 2.3384075 | G17: 2.3384075 | H17: 2.3384075 | I17: 2.3384075 | J17: 2.3384075 | K17: 2.3384075 | L17: 2.3384075
D18: Juice or Laban or Yoghart | E18: 1 | F18: ='Raw material list'!F147 -> 0.012272727 | G18: 0.012272727 | H18: 0.012272727 | I18: 0.012272727 | J18: 0.012272727 | K18: 0.012272727 | L18: 0.012272727
D19: Water | E19: 2 | F19: =0.3875*2 -> 0.775 | G19: =0.3875*2 -> 0.775 | H19: =0.3875*2 -> 0.775 | I19: =0.3875*2 -> 0.775 | J19: =0.3875*2 -> 0.775 | K19: =0.3875*2 -> 0.775 | L19: =0.3875*2 -> 0.775
D20: Cutlaries | E20: 1 | M20: Packing
C21: Dinner | D21: Soup | E21: 1 | F21: ='Sunday '!G50 -> 0.94078914 | G21: =Monday!G48 -> 0.84124892 | H21: =Tuesday!G49 -> 0.87605056 | I21: =Wednesday!G50 -> 0.82965491 | J21: =Thursday!G49 -> 0.94078914 | K21: ='Friday '!G47 -> 1.0261522 | L21: ='Saturday '!G49 -> 0.93023921
D22: Salad | E22: 1 | F22: ='Sunday '!G53 -> 1.2029384 | G22: =Monday!G51 -> 1.2029384 | H22: =Tuesday!G52 -> 1.2029384 | I22: =Wednesday!G53 -> 1.2029384 | J22: =Thursday!G52 -> 1.2029384 | K22: ='Friday '!G50 -> 1.2029384 | L22: ='Saturday '!G52 -> 1.2029384
D23: Main course (Ckicken,Beef, Fish) or Sandwich or Vegitable | E23: 1 | F23: =MAX('Sunday '!G58:G66) -> 6.530119 | G23: =MAX(Monday!G56:G64) -> 5.7769184 | H23: =MAX(Tuesday!G57:G65) -> 6.0950544 | I23: =MAX(Wednesday!G58:G66) -> 6.0607559 | J23: =MAX(Thursday!G57:G65) -> 5.033731 | K23: =MAX('Friday '!G53:G62) -> 7.3655786 | L23: =MAX('Saturday '!G57:G65) -> 5.033731
D24: Dessert | E24: 1 | F24: ='Sunday '!G44 -> 0.94041226 | G24: =Monday!G43 -> 0.91422879 | H24: =Tuesday!G44 -> 0.91376546 | I24: =Wednesday!G44 -> 0.89719994 | J24: =Thursday!G43 -> 0.87980433 | K24: ='Friday '!G42 -> 0.89719994 | L24: ='Saturday '!G44 -> 0.89719994
D25: Juice or Laban or Yoghart | E25: 1 | F25: =F18 -> 0.012272727 | G25: 0.012272727 | H25: 0.012272727 | I25: 0.012272727 | J25: 0.012272727 | K25: 0.012272727 | L25: 0.012272727
D26: Water | E26: 2 | F26: =0.3875*2 -> 0.775 | G26: =0.3875*2 -> 0.775 | H26: =0.3875*2 -> 0.775 | I26: =0.3875*2 -> 0.775 | J26: =0.3875*2 -> 0.775 | K26: =0.3875*2 -> 0.775 | L26: =0.3875*2 -> 0.775
D27: Cutlaries | E27: 1 | M27: Packing
C28: Snacks | D28: Water | E28: 1 | F28: =0.3875 -> 0.3875 | G28: =0.3875 -> 0.3875 | H28: =0.3875 -> 0.3875 | I28: =0.3875 -> 0.3875 | J28: =0.3875 -> 0.3875 | K28: =0.3875 -> 0.3875 | L28: =0.3875 -> 0.3875
D29: English Cake or Muffin | E29: 1 | F29: ='Master – Recipes'!J82 -> 0.55247265 | G29: 0.55247265 | H29: 0.55247265 | I29: 0.55247265 | J29: 0.55247265 | K29: 0.55247265 | L29: 0.55247265
D30: Tea Set or Coffee with cup and Lid | E30: 1 | F30: =F7 -> 0.035 | G30: 0.035 | H30: 0.035 | I30: 0.035 | J30: 0.035 | K30: 0.035 | L30: 0.035
D31: Average Food Cost per patient | F31: =SUM(F5:F30) -> 30.49578 | G31: =SUM(G5:G30) -> 27.53318 | H31: =SUM(H5:H30) -> 25.811576 | I31: =SUM(I5:I30) -> 26.659714 | J31: =SUM(J5:J30) -> 28.342578 | K31: =SUM(K5:K30) -> 28.061302 | L31: =SUM(L5:L30) -> 25.313712
D32: Packing Cost | F32: ='Packing Cost'!H31 -> 6.21856 | G32: 6.21856 | H32: 6.21856 | I32: 6.21856 | J32: 6.21856 | K32: 6.21856 | L32: 6.21856
D33: Labour Cost | E33: assumed | F33: 10 | G33: 10 | H33: 10 | I33: 10 | J33: 10 | K33: 10 | L33: 10
D34: Delivery Cost | E34: assumed | F34: 8 | G34: 8 | H34: 8 | I34: 8 | J34: 8 | K34: 8 | L34: 8
D35: Total Cost Per Patient | F35: =SUM(F31:F34) -> 54.71434 | G35: =SUM(G31:G34) -> 51.75174 | H35: =SUM(H31:H34) -> 50.030136 | I35: =SUM(I31:I34) -> 50.878274 | J35: =SUM(J31:J34) -> 52.561138 | K35: =SUM(K31:K34) -> 52.279862 | L35: =SUM(L31:L34) -> 49.532272

Sheet Saturday 
A1: BREAKFAST & LUNCH & DINNER INPATIENTS MENU 2026
A2: DIET TYPE | B2: Saturday | C2: Average cooking Weight per in-Patient | F2: Food Cost | G2: ='Sunday '!G3 -> Avg.Food Cost
B3: BREAKFAST | C3: UOM | D3: Minimum | E3: Maximum
A4: category | B4: Main Course Breakfast
A5: RD | B5: Croissant Cheese and Foul Meddames | C5: Gram | D5: 180 | E5: 200 | F5: ='Master – Recipes'!J124+'Master – Recipes'!J125 -> 1.5496102
A6: DM/ CARDIAC | B6: Foul and Labneh | C6: Gram | D6: 180 | E6: 200 | F6: ='Master – Recipes'!J125+'Master – Recipes'!J126 -> 2.3675044
A7: RENAL | B7: Labneh and Boiled Egg | C7: Gram | D7: Scope 80 Grm | F7: ='Master – Recipes'!J126+'Master – Recipes'!J127 -> 2.0236299
A8: DM/ CARDIAC | B8: Boiled Egg 1 Pcs and Foul | C8: Gram | D8: 180 | E8: 200 | F8: ='Master – Recipes'!J127+'Master – Recipes'!J125 -> 1.5539903
A9: SD | B9: (Soft Diet) Fruits Pudding and Boiled egg | F9: ='Master – Recipes'!J128+'Master – Recipes'!J127 -> 2.0381086
A10: category | B10: Side Items Breakfast
A11: RD/ DM / CARDIAC | B11: Sliced Vegetables with Olives | F11: ='Master – Recipes'!J131 -> 0.80984619
A12: ALL DIETS | B12: TEA SET PACKET | F12: 1 | G12: =AVERAGE(F5:F12) -> 1.6203842
B13: LUNCH
A14: Category | B14: Soup
A15: REGULAR DIET / DIABETIC DIET | B15: Turkish Red Lentil Soup | C15: ML | D15: 180 | E15: 200 | F15: ='Master – Recipes'!J121 -> 0.5598686
A16: REGULAR DIET / DIABETIC DIET | B16: Cream of Chicken Soup | C16: ML | D16: 180 | E16: 200 | F16: ='Master – Recipes'!J123 -> 1.0430936
A17: CLEAR LIQUID DIET | B17: Clear Soup | C17: ML | D17: 180 | E17: 200 | F17: =F49 -> 0.7437073
A18: SOFT DIET | B18: Strained Cream of Chicken Soup | C18: ML | D18: 180 | E18: 200 | F18: ='Master – Recipes'!J102 -> 1.0441412 | G18: =AVERAGE(F15:F18) -> 0.84770267
A19: Category | B19: Salad
A20: REGULAR DIET / DIABETIC DIET | B20: GREEK SALAD With Lemon Dressing | C20: Gram | D20: 125 | E20: 180 | F20: ='Master – Recipes'!J160 -> 1.9849722
A21: SOFT DIET | B21: SPECIAL DIET SALAD ( Lettuce, peeled cucumber and Shredded Carrots ) | C21: Gram | D21: 125 | E21: 180 | F21: =F52 -> 1.4287088 | G21: =AVERAGE(F20:F21) -> 1.7068405
A22: Category | B22: Main Course - Lunch
A23: REGULAR DIET / DIABETIC DIET | B23: Chicken Butter Sauce With White Rice | C23: Gram | D23: 380 | E23: 460 | F23: ='Master – Recipes'!J53 -> 6.4857536
A24: REGULAR DIET / DIABETIC DIET | B24: Seafood Sayadeya with Tahina Sauce | C24: Gram | D24: 380 | E24: 460 | F24: ='Master – Recipes'!J16 -> 5.1319822
A25: REGULAR DIET / DIABETIC DIET | B25: Beef Spaghetti Bolognese | C25: Gram | D25: 380 | E25: 460 | F25: ='Master – Recipes'!J52 -> 6.4281519 | G25: =AVERAGE(F23:F25) -> 6.0152959
A26: Category | B26: Daily Main Course - Lunch
A27: REGULAR DIET / DIABETIC DIET | B27: Chicken Curry with White Rice | C27: Gram | D27: 380 | E27: 460 | F27: ='Master – Recipes'!J63 -> 5.9948634
A28: ANTI D DIET | B28: Boiled Chicken with Soft Rice/ Boiled potato and Boiled Vegetables | C28: Gram | D28: 280 | E28: 350 | F28: ='Master – Recipes'!J71 -> 5.1052596
A29: CARDIAC DIET | B29: low sodium low Seasoning Grilled Chicken Breast with white Rice, Sauteed Mixed Veggies & Vegetarian Edam Cut Beans stew | C29: Gram | D29: 280 | E29: 350 | F29: ='Master – Recipes'!J61 -> 6.3497875
